Workbook

Sheet Cover
C3: Análise Same Sellers Tik Tok
C7: xxx
C9: xxx
C11: Amz x Shopee Comparisons
C12: xxx

Sheet Analysis Table
B3: TABELA DE SUPORTE PARA ANÁLISE
C7: shop_id_shp | D7: shop_name_shp | E7: shop_id_tts | F7: shop_name_tts | G7: cluster | H7: net_ado_shp | I7: net_adnmv_usd_shp | J7: net_ado_tts | K7: net_adnmv_usd_tts | L7: source | M7: top_at_shp | N7: top_at_tts | O7: top_at_both | P7: bigger_at_shp | Q7: duplicates
C8: 291174073 | D8: ZSZ_Official Store | E8: =_xlfn.XLOOKUP(C8,'Same Seller Hist'!E:E,'Same Seller Hist'!I:I) -> 7.4961635e+18 | F8: =_xlfn.XLOOKUP(C8,'Same Seller Hist'!E:E,'Same Seller Hist'!H:H) -> ZSZ BR | G8: CN | H8: 1622 | I8: 9436.935 | J8: =_xlfn.IFNA(_xlfn.XLOOKUP(F8,'Fastmoss 500'!D:D,'Fastmoss 500'!O:O),0) -> 700 | K8: =_xlfn.IFNA(_xlfn.XLOOKUP(F8,'Fastmoss 500'!D:D,'Fastmoss 500'!N:N),0) -> 14158.065 | L8: Shp 500 | M8: =IF(L8="Shp 500","Sim",IF(ISNA(_xlfn.XLOOKUP(C8,'Shp 500'!D:D,'Shp 500'!D:D)),"Não","Sim")) -> Sim | N8: =IF(L8="Fastmoss 500","Sim",IF(ISNA(_xlfn.XLOOKUP(_xlfn.XLOOKUP(C8,'Same Seller Hist'!E:E,'Same Seller Hist'!H:H),'Fastmoss 500'!D:D,'Fastmoss 500'!D:D)),"Não","Sim")) -> Sim | O8: =IF(AND(M8="Sim",N8="Sim"),"Sim","Não") -> Sim | P8: =IF(I8>K8,"Sim","Não") -> Não | Q8: =COUNTIFS(C:C,C8) -> 1
C9: 552896405 | D9: Casa_Completa_Enxovais | E9: =_xlfn.XLOOKUP(C9,'Same Seller Hist'!E:E,'Same Seller Hist'!I:I) -> 7.49626e+18 | F9: =_xlfn.XLOOKUP(C9,'Same Seller Hist'!E:E,'Same Seller Hist'!H:H) -> Casa Completa Enxovais | G9: Lifestyle | H9: 5043.8387 | I9: 53289.304 | J9: =_xlfn.IFNA(_xlfn.XLOOKUP(F9,'Fastmoss 500'!D:D,'Fastmoss 500'!O:O),0) -> 0 | K9: =_xlfn.IFNA(_xlfn.XLOOKUP(F9,'Fastmoss 500'!D:D,'Fastmoss 500'!N:N),0) -> 0 | L9: Shp 500 | M9: =IF(L9="Shp 500","Sim",IF(ISNA(_xlfn.XLOOKUP(C9,'Shp 500'!D:D,'Shp 500'!D:D)),"Não","Sim")) -> Sim | N9: =IF(L9="Fastmoss 500","Sim",IF(ISNA(_xlfn.XLOOKUP(_xlfn.XLOOKUP(C9,'Same Seller Hist'!E:E,'Same Seller Hist'!H:H),'Fastmoss 500'!D:D,'Fastmoss 500'!D:D)),"Não","Sim")) -> Não | O9: =IF(AND(M9="Sim",N9="Sim"),"Sim","Não") -> Não | P9: =IF(I9>K9,"Sim","Não") -> Sim | Q9: =COUNTIFS(C:C,C9) -> 1
C10: 974102638 | D10: Loja 128 | E10: =_xlfn.XLOOKUP(C10,'Same Seller Hist'!E:E,'Same Seller Hist'!I:I) -> 7.4962283e+18 | F10: =_xlfn.XLOOKUP(C10,'Same Seller Hist'!E:E,'Same Seller Hist'!H:H) -> blueepulse | G10: CN | H10: 4870.1613 | I10: 49065.871 | J10: =_xlfn.IFNA(_xlfn.XLOOKUP(F10,'Fastmoss 500'!D:D,'Fastmoss 500'!O:O),0) -> 0 | K10: =_xlfn.IFNA(_xlfn.XLOOKUP(F10,'Fastmoss 500'!D:D,'Fastmoss 500'!N:N),0) -> 0 | L10: Shp 500 | M10: =IF(L10="Shp 500","Sim",IF(ISNA(_xlfn.XLOOKUP(C10,'Shp 500'!D:D,'Shp 500'!D:D)),"Não","Sim")) -> Sim | N10: =IF(L10="Fastmoss 500","Sim",IF(ISNA(_xlfn.XLOOKUP(_xlfn.XLOOKUP(C10,'Same Seller Hist'!E:E,'Same Seller Hist'!H:H),'Fastmoss 500'!D:D,'Fastmoss 500'!D:D)),"Não","Sim")) -> Não | O10: =IF(AND(M10="Sim",N10="Sim"),"Sim","Não") -> Não | P10: =IF(I10>K10,"Sim","Não") -> Sim | Q10: =COUNTIFS(C:C,C10) -> 1
C11: 362859393 | D11: ALFA MERCEARIA.BR | E11: =_xlfn.XLOOKUP(C11,'Same Seller Hist'!E:E,'Same Seller Hist'!I:I) -> 7.4961597e+18 | F11: =_xlfn.XLOOKUP(C11,'Same Seller Hist'!E:E,'Same Seller Hist'!H:H) -> ALFA SHOP.BR | G11: CN | H11: 4604.9355 | I11: 14928.731 | J11: =_xlfn.IFNA(_xlfn.XLOOKUP(F11,'Fastmoss 500'!D:D,'Fastmoss 500'!O:O),0) -> 0 | K11: =_xlfn.IFNA(_xlfn.XLOOKUP(F11,'Fastmoss 500'!D:D,'Fastmoss 500'!N:N),0) -> 0 | L11: Shp 500 | M11: =IF(L11="Shp 500","Sim",IF(ISNA(_xlfn.XLOOKUP(C11,'Shp 500'!D:D,'Shp 500'!D:D)),"Não","Sim")) -> Sim | N11: =IF(L11="Fastmoss 500","Sim",IF(ISNA(_xlfn.XLOOKUP(_xlfn.XLOOKUP(C11,'Same Seller Hist'!E:E,'Same Seller Hist'!H:H),'Fastmoss 500'!D:D,'Fastmoss 500'!D:D)),"Não","Sim")) -> Não | O11: =IF(AND(M11="Sim",N11="Sim"),"Sim","Não") -> Não | P11: =IF(I11>K11,"Sim","Não") -> Sim | Q11: =COUNTIFS(C:C,C11) -> 1
C12: 1045085918 | D12: Droga Clara | E12: =_xlfn.XLOOKUP(C12,'Same Seller Hist'!E:E,'Same Seller Hist'!I:I) -> 7.4941815e+18 | F12: =_xlfn.XLOOKUP(C12,'Same Seller Hist'!E:E,'Same Seller Hist'!H:H) -> YUMI CELL BR | G12: FMCG | H12: 4299.4839 | I12: 22995.675 | J12: =_xlfn.IFNA(_xlfn.XLOOKUP(F12,'Fastmoss 500'!D:D,'Fastmoss 500'!O:O),0) -> 235.48387 | K12: =_xlfn.IFNA(_xlfn.XLOOKUP(F12,'Fastmoss 500'!D:D,'Fastmoss 500'!N:N),0) -> 17706.452 | L12: Shp 500 | M12: =IF(L12="Shp 500","Sim",IF(ISNA(_xlfn.XLOOKUP(C12,'Shp 500'!D:D,'Shp 500'!D:D)),"Não","Sim")) -> Sim | N12: =IF(L12="Fastmoss 500","Sim",IF(ISNA(_xlfn.XLOOKUP(_xlfn.XLOOKUP(C12,'Same Seller Hist'!E:E,'Same Seller Hist'!H:H),'Fastmoss 500'!D:D,'Fastmoss 500'!D:D)),"Não","Sim")) -> Sim | O12: =IF(AND(M12="Sim",N12="Sim"),"Sim","Não") -> Sim | P12: =IF(I12>K12,"Sim","Não") -> Sim | Q12: =COUNTIFS(C:C,C12) -> 1
C13: 296363855 | D13: CasaLauraEnxovais | E13: =_xlfn.XLOOKUP(C13,'Same Seller Hist'!E:E,'Same Seller Hist'!I:I) -> 7.4955619e+18 | F13: =_xlfn.XLOOKUP(C13,'Same Seller Hist'!E:E,'Same Seller Hist'!H:H) -> Casa Laura Enxovais | G13: Lifestyle | H13: 1873.9355 | I13: 15155.613 | J13: =_xlfn.IFNA(_xlfn.XLOOKUP(F13,'Fastmoss 500'!D:D,'Fastmoss 500'!O:O),0) -> 280.64516 | K13: =_xlfn.IFNA(_xlfn.XLOOKUP(F13,'Fastmoss 500'!D:D,'Fastmoss 500'!N:N),0) -> 16445.161 | L13: Shp 500 | M13: =IF(L13="Shp 500","Sim",IF(ISNA(_xlfn.XLOOKUP(C13,'Shp 500'!D:D,'Shp 500'!D:D)),"Não","Sim")) -> Sim | N13: =IF(L13="Fastmoss 500","Sim",IF(ISNA(_xlfn.XLOOKUP(_xlfn.XLOOKUP(C13,'Same Seller Hist'!E:E,'Same Seller Hist'!H:H),'Fastmoss 500'!D:D,'Fastmoss 500'!D:D)),"Não","Sim")) -> Sim | O13: =IF(AND(M13="Sim",N13="Sim"),"Sim","Não") -> Sim | P13: =IF(I13>K13,"Sim","Não") -> Não | Q13: =COUNTIFS(C:C,C13) -> 1
C14: 872424585 | D14: Mega TechStore | E14: =_xlfn.XLOOKUP(C14,'Same Seller Hist'!E:E,'Same Seller Hist'!I:I) -> 7.4961817e+18 | F14: =_xlfn.XLOOKUP(C14,'Same Seller Hist'!E:E,'Same Seller Hist'!H:H) -> mega tech store | G14: CN | H14: 3866.0645 | I14: 31272.972 | J14: =_xlfn.IFNA(_xlfn.XLOOKUP(F14,'Fastmoss 500'!D:D,'Fastmoss 500'!O:O),0) -> 0 | K14: =_xlfn.IFNA(_xlfn.XLOOKUP(F14,'Fastmoss 500'!D:D,'Fastmoss 500'!N:N),0) -> 0 | L14: Shp 500 | M14: =IF(L14="Shp 500","Sim",IF(ISNA(_xlfn.XLOOKUP(C14,'Shp 500'!D:D,'Shp 500'!D:D)),"Não","Sim")) -> Sim | N14: =IF(L14="Fastmoss 500","Sim",IF(ISNA(_xlfn.XLOOKUP(_xlfn.XLOOKUP(C14,'Same Seller Hist'!E:E,'Same Seller Hist'!H:H),'Fastmoss 500'!D:D,'Fastmoss 500'!D:D)),"Não","Sim")) -> Não | O14: =IF(AND(M14="Sim",N14="Sim"),"Sim","Não") -> Não | P14: =IF(I14>K14,"Sim","Não") -> Sim | Q14: =COUNTIFS(C:C,C14) -> 1
C15: 643719371 | D15: NEWCOOL | E15: =_xlfn.XLOOKUP(C15,'Same Seller Hist'!E:E,'Same Seller Hist'!I:I) -> 7.496184e+18 | F15: =_xlfn.XLOOKUP(C15,'Same Seller Hist'!E:E,'Same Seller Hist'!H:H) -> NEWCOOL.BR | G15: CN | H15: 3826.9355 | I15: 19013.021 | J15: =_xlfn.IFNA(_xlfn.XLOOKUP(F15,'Fastmoss 500'!D:D,'Fastmoss 500'!O:O),0) -> 0 | K15: =_xlfn.IFNA(_xlfn.XLOOKUP(F15,'Fastmoss 500'!D:D,'Fastmoss 500'!N:N),0) -> 0 | L15: Shp 500 | M15: =IF(L15="Shp 500","Sim",IF(ISNA(_xlfn.XLOOKUP(C15,'Shp 500'!D:D,'Shp 500'!D:D)),"Não","Sim")) -> Sim | N15: =IF(L15="Fastmoss 500","Sim",IF(ISNA(_xlfn.XLOOKUP(_xlfn.XLOOKUP(C15,'Same Seller Hist'!E:E,'Same Seller Hist'!H:H),'Fastmoss 500'!D:D,'Fastmoss 500'!D:D)),"Não","Sim")) -> Não | O15: =IF(AND(M15="Sim",N15="Sim"),"Sim","Não") -> Não | P15: =IF(I15>K15,"Sim","Não") -> Sim | Q15: =COUNTIFS(C:C,C15) -> 1
C16: 299222557 | D16: RIven Bazar | E16: =_xlfn.XLOOKUP(C16,'Same Seller Hist'!E:E,'Same Seller Hist'!I:I) -> 7.4961792e+18 | F16: =_xlfn.XLOOKUP(C16,'Same Seller Hist'!E:E,'Same Seller Hist'!H:H) -> RIVEN BAZAR | G16: CN | H16: 2540.1613 | I16: 9178.8417 | J16: =_xlfn.IFNA(_xlfn.XLOOKUP(F16,'Fastmoss 500'!D:D,'Fastmoss 500'!O:O),0) -> 251.6129 | K16: =_xlfn.IFNA(_xlfn.XLOOKUP(F16,'Fastmoss 500'!D:D,'Fastmoss 500'!N:N),0) -> 10303.226 | L16: Shp 500 | M16: =IF(L16="Shp 500","Sim",IF(ISNA(_xlfn.XLOOKUP(C16,'Shp 500'!D:D,'Shp 500'!D:D)),"Não","Sim")) -> Sim | N16: =IF(L16="Fastmoss 500","Sim",IF(ISNA(_xlfn.XLOOKUP(_xlfn.XLOOKUP(C16,'Same Seller Hist'!E:E,'Same Seller Hist'!H:H),'Fastmoss 500'!D:D,'Fastmoss 500'!D:D)),"Não","Sim")) -> Sim | O16: =IF(AND(M16="Sim",N16="Sim"),"Sim","Não") -> Sim | P16: =IF(I16>K16,"Sim","Não") -> Não | Q16: =COUNTIFS(C:C,C16) -> 1
C17: 1064041485 | D17: LuxeElectra | E17: =_xlfn.XLOOKUP(C17,'Same Seller Hist'!E:E,'Same Seller Hist'!I:I) -> 7.4961859e+18 | F17: =_xlfn.XLOOKUP(C17,'Same Seller Hist'!E:E,'Same Seller Hist'!H:H) -> luxeelectra | G17: CN | H17: 3451.0968 | I17: 33941.769 | J17: =_xlfn.IFNA(_xlfn.XLOOKUP(F17,'Fastmoss 500'!D:D,'Fastmoss 500'!O:O),0) -> 0 | K17: =_xlfn.IFNA(_xlfn.XLOOKUP(F17,'Fastmoss 500'!D:D,'Fastmoss 500'!N:N),0) -> 0 | L17: Shp 500 | M17: =IF(L17="Shp 500","Sim",IF(ISNA(_xlfn.XLOOKUP(C17,'Shp 500'!D:D,'Shp 500'!D:D)),"Não","Sim")) -> Sim | N17: =IF(L17="Fastmoss 500","Sim",IF(ISNA(_xlfn.XLOOKUP(_xlfn.XLOOKUP(C17,'Same Seller Hist'!E:E,'Same Seller Hist'!H:H),'Fastmoss 500'!D:D,'Fastmoss 500'!D:D)),"Não","Sim")) -> Não | O17: =IF(AND(M17="Sim",N17="Sim"),"Sim","Não") -> Não | P17: =IF(I17>K17,"Sim","Não") -> Sim | Q17: =COUNTIFS(C:C,C17) -> 1
C18: 341167297 | D18: Poloinfantil.store | E18: =_xlfn.XLOOKUP(C18,'Same Seller Hist'!E:E,'Same Seller Hist'!I:I) -> 0 | F18: =_xlfn.XLOOKUP(C18,'Same Seller Hist'!E:E,'Same Seller Hist'!H:H) -> 0 | G18: Fashion | H18: 3346.871 | I18: 37236.535 | J18: =_xlfn.IFNA(_xlfn.XLOOKUP(F18,'Fastmoss 500'!D:D,'Fastmoss 500'!O:O),0) -> 0 | K18: =_xlfn.IFNA(_xlfn.XLOOKUP(F18,'Fastmoss 500'!D:D,'Fastmoss 500'!N:N),0) -> 0 | L18: Shp 500 | M18: =IF(L18="Shp 500","Sim",IF(ISNA(_xlfn.XLOOKUP(C18,'Shp 500'!D:D,'Shp 500'!D:D)),"Não","Sim")) -> Sim | N18: =IF(L18="Fastmoss 500","Sim",IF(ISNA(_xlfn.XLOOKUP(_xlfn.XLOOKUP(C18,'Same Seller Hist'!E:E,'Same Seller Hist'!H:H),'Fastmoss 500'!D:D,'Fastmoss 500'!D:D)),"Não","Sim")) -> Não | O18: =IF(AND(M18="Sim",N18="Sim"),"Sim","Não") -> Não | P18: =IF(I18>K18,"Sim","Não") -> Sim | Q18: =COUNTIFS(C:C,C18) -> 1
C19: 313660590 | D19: Nosso Lar Enxovais | E19: =_xlfn.XLOOKUP(C19,'Same Seller Hist'!E:E,'Same Seller Hist'!I:I) -> 7.4940983e+18 | F19: =_xlfn.XLOOKUP(C19,'Same Seller Hist'!E:E,'Same Seller Hist'!H:H) -> Nosso Lar Enxovais | G19: Lifestyle | H19: 3313.3226 | I19: 29155.732 | J19: =_xlfn.IFNA(_xlfn.XLOOKUP(F19,'Fastmoss 500'!D:D,'Fastmoss 500'!O:O),0) -> 0 | K19: =_xlfn.IFNA(_xlfn.XLOOKUP(F19,'Fastmoss 500'!D:D,'Fastmoss 500'!N:N),0) -> 0 | L19: Shp 500 | M19: =IF(L19="Shp 500","Sim",IF(ISNA(_xlfn.XLOOKUP(C19,'Shp 500'!D:D,'Shp 500'!D:D)),"Não","Sim")) -> Sim | N19: =IF(L19="Fastmoss 500","Sim",IF(ISNA(_xlfn.XLOOKUP(_xlfn.XLOOKUP(C19,'Same Seller Hist'!E:E,'Same Seller Hist'!H:H),'Fastmoss 500'!D:D,'Fastmoss 500'!D:D)),"Não","Sim")) -> Não | O19: =IF(AND(M19="Sim",N19="Sim"),"Sim","Não") -> Não | P19: =IF(I19>K19,"Sim","Não") -> Sim | Q19: =COUNTIFS(C:C,C19) -> 1
... C140: 324536294 | D140: Krokodilus Oficial | E140: =_xlfn.XLOOKUP(C140,'Same Seller Hist'!E:E,'Same Seller Hist'!I:I) -> 7.4961604e+18 | F140: =_xlfn.XLOOKUP(C140,'Same Seller Hist'!E:E,'Same Seller Hist'!H:H) -> Krokodilus | G140: Fashion | H140: 819.80645 | I140: 15741.058 | J140: =_xlfn.IFNA(_xlfn.XLOOKUP(F140,'Fastmoss 500'!D:D,'Fastmoss 500'!O:O),0) -> 0 | K140: =_xlfn.IFNA(_xlfn.XLOOKUP(F140,'Fastmoss 500'!D:D,'Fastmoss 500'!N:N),0) -> 0 | L140: Shp 500 | M140: =IF(L140="Shp 500","Sim",IF(ISNA(_xlfn.XLOOKUP(C140,'Shp 500'!D:D,'Shp 500'!D:D)),"Não","Sim")) -> Sim | N140: =IF(L140="Fastmoss 500","Sim",IF(ISNA(_xlfn.XLOOKUP(_xlfn.XLOOKUP(C140,'Same Seller Hist'!E:E,'Same Seller Hist'!H:H),'Fastmoss 500'!D:D,'Fastmoss 500'!D:D)),"Não","Sim")) -> Não | O140: =IF(AND(M140="Sim",N140="Sim"),"Sim","Não") -> Não | P140: =IF(I140>K140,"Sim","Não") -> Sim | Q140: =COUNTIFS(C:C,C140) -> 1
C141: =_xlfn.XLOOKUP(F141,'Same Seller Hist'!H:H,'Same Seller Hist'!E:E) -> 1543591764 | D141: =_xlfn.XLOOKUP(F141,'Same Seller Hist'!H:H,'Same Seller Hist'!D:D) -> Always Fit Suplementos | E141: =_xlfn.XLOOKUP(F141,'Same Seller Hist'!H:H,'Same Seller Hist'!I:I) -> 7.4962164e+18 | F141: Always Fit Suplementos | G141: =_xlfn.XLOOKUP(C141,'Same Seller Hist'!E:E,'Same Seller Hist'!F:F) -> FMCG | H141: =_xlfn.IFNA(_xlfn.XLOOKUP(C141,'Shp 500'!D:D,'Shp 500'!I:I),0) -> 0 | I141: =_xlfn.IFNA(_xlfn.XLOOKUP(C141,'Shp 500'!D:D,'Shp 500'!J:J),0) -> 0 | J141: 5883.871 | K141: 303225.81 | L141: Fastmoss 500 | M141: =IF(L141="Shp 500","Sim",IF(ISNA(_xlfn.XLOOKUP(C141,'Shp 500'!D:D,'Shp 500'!D:D)),"Não","Sim")) -> Não | N141: =IF(L141="Fastmoss 500","Sim",IF(ISNA(_xlfn.XLOOKUP(_xlfn.XLOOKUP(C141,'Same Seller Hist'!E:E,'Same Seller Hist'!H:H),'Fastmoss 500'!D:D,'Fastmoss 500'!D:D)),"Não","Sim")) -> Sim | O141: =IF(AND(M141="Sim",N141="Sim"),"Sim","Não") -> Não | P141: =IF(I141>K141,"Sim","Não") -> Não | Q141: =COUNTIFS(C:C,C141) -> 1
C142: 616222685 | D142: Salon Line | E142: =_xlfn.XLOOKUP(C142,'Same Seller Hist'!E:E,'Same Seller Hist'!I:I) -> 7.496153e+18 | F142: =_xlfn.XLOOKUP(C142,'Same Seller Hist'!E:E,'Same Seller Hist'!H:H) -> Salon Line | G142: FMCG | H142: 5865.1935 | I142: 37595.714 | J142: =_xlfn.IFNA(_xlfn.XLOOKUP(F142,'Fastmoss 500'!D:D,'Fastmoss 500'!O:O),0) -> 541.93548 | K142: =_xlfn.IFNA(_xlfn.XLOOKUP(F142,'Fastmoss 500'!D:D,'Fastmoss 500'!N:N),0) -> 21870.968 | L142: Shp 500 | M142: =IF(L142="Shp 500","Sim",IF(ISNA(_xlfn.XLOOKUP(C142,'Shp 500'!D:D,'Shp 500'!D:D)),"Não","Sim")) -> Sim | N142: =IF(L142="Fastmoss 500","Sim",IF(ISNA(_xlfn.XLOOKUP(_xlfn.XLOOKUP(C142,'Same Seller Hist'!E:E,'Same Seller Hist'!H:H),'Fastmoss 500'!D:D,'Fastmoss 500'!D:D)),"Não","Sim")) -> Sim | O142: =IF(AND(M142="Sim",N142="Sim"),"Sim","Não") -> Sim | P142: =IF(I142>K142,"Sim","Não") -> Sim | Q142: =COUNTIFS(C:C,C142) -> 1
C143: =_xlfn.XLOOKUP(F143,'Same Seller Hist'!H:H,'Same Seller Hist'!E:E) -> 906473022 | D143: =_xlfn.XLOOKUP(F143,'Same Seller Hist'!H:H,'Same Seller Hist'!D:D) -> LUNA SHOP_BRASIL | E143: =_xlfn.XLOOKUP(F143,'Same Seller Hist'!H:H,'Same Seller Hist'!I:I) -> 7.4941342e+18 | F143: LUNA SHOP_BRASIL | G143: =_xlfn.XLOOKUP(C143,'Same Seller Hist'!E:E,'Same Seller Hist'!F:F) -> FMCG | H143: =_xlfn.IFNA(_xlfn.XLOOKUP(C143,'Shp 500'!D:D,'Shp 500'!I:I),0) -> 0 | I143: =_xlfn.IFNA(_xlfn.XLOOKUP(C143,'Shp 500'!D:D,'Shp 500'!J:J),0) -> 0 | J143: 3293.5484 | K143: 93548.387 | L143: Fastmoss 500 | M143: =IF(L143="Shp 500","Sim",IF(ISNA(_xlfn.XLOOKUP(C143,'Shp 500'!D:D,'Shp 500'!D:D)),"Não","Sim")) -> Não | N143: =IF(L143="Fastmoss 500","Sim",IF(ISNA(_xlfn.XLOOKUP(_xlfn.XLOOKUP(C143,'Same Seller Hist'!E:E,'Same Seller Hist'!H:H),'Fastmoss 500'!D:D,'Fastmoss 500'!D:D)),"Não","Sim")) -> Sim | O143: =IF(AND(M143="Sim",N143="Sim"),"Sim","Não") -> Não | P143: =IF(I143>K143,"Sim","Não") -> Não | Q143: =COUNTIFS(C:C,C143) -> 1
C144: =_xlfn.XLOOKUP(F144,'Same Seller Hist'!H:H,'Same Seller Hist'!E:E) -> 1103632656 | D144: =_xlfn.XLOOKUP(F144,'Same Seller Hist'!H:H,'Same Seller Hist'!D:D) -> Express.Loja | E144: =_xlfn.XLOOKUP(F144,'Same Seller Hist'!H:H,'Same Seller Hist'!I:I) -> 7.4961636e+18 | F144: Express.Loja | G144: =_xlfn.XLOOKUP(C144,'Same Seller Hist'!E:E,'Same Seller Hist'!F:F) -> Lifestyle | H144: =_xlfn.IFNA(_xlfn.XLOOKUP(C144,'Shp 500'!D:D,'Shp 500'!I:I),0) -> 0 | I144: =_xlfn.IFNA(_xlfn.XLOOKUP(C144,'Shp 500'!D:D,'Shp 500'!J:J),0) -> 0 | J144: 2551.6129 | K144: 41935.484 | L144: Fastmoss 500 | M144: =IF(L144="Shp 500","Sim",IF(ISNA(_xlfn.XLOOKUP(C144,'Shp 500'!D:D,'Shp 500'!D:D)),"Não","Sim")) -> Não | N144: =IF(L144="Fastmoss 500","Sim",IF(ISNA(_xlfn.XLOOKUP(_xlfn.XLOOKUP(C144,'Same Seller Hist'!E:E,'Same Seller Hist'!H:H),'Fastmoss 500'!D:D,'Fastmoss 500'!D:D)),"Não","Sim")) -> Sim | O144: =IF(AND(M144="Sim",N144="Sim"),"Sim","Não") -> Não | P144: =IF(I144>K144,"Sim","Não") -> Não | Q144: =COUNTIFS(C:C,C144) -> 1
C145: =_xlfn.XLOOKUP(F145,'Same Seller Hist'!H:H,'Same Seller Hist'!E:E) -> 1579330222 | D145: =_xlfn.XLOOKUP(F145,'Same Seller Hist'!H:H,'Same Seller Hist'!D:D) -> Barbour's Beauty | E145: =_xlfn.XLOOKUP(F145,'Same Seller Hist'!H:H,'Same Seller Hist'!I:I) -> 7.4962632e+18 | F145: Barbour's Beauty | G145: =_xlfn.XLOOKUP(C145,'Same Seller Hist'!E:E,'Same Seller Hist'!F:F) -> FMCG | H145: =_xlfn.IFNA(_xlfn.XLOOKUP(C145,'Shp 500'!D:D,'Shp 500'!I:I),0) -> 0 | I145: =_xlfn.IFNA(_xlfn.XLOOKUP(C145,'Shp 500'!D:D,'Shp 500'!J:J),0) -> 0 | J145: 2038.7097 | K145: 112903.23 | L145: Fastmoss 500 | M145: =IF(L145="Shp 500","Sim",IF(ISNA(_xlfn.XLOOKUP(C145,'Shp 500'!D:D,'Shp 500'!D:D)),"Não","Sim")) -> Não | N145: =IF(L145="Fastmoss 500","Sim",IF(ISNA(_xlfn.XLOOKUP(_xlfn.XLOOKUP(C145,'Same Seller Hist'!E:E,'Same Seller Hist'!H:H),'Fastmoss 500'!D:D,'Fastmoss 500'!D:D)),"Não","Sim")) -> Sim | O145: =IF(AND(M145="Sim",N145="Sim"),"Sim","Não") -> Não | P145: =IF(I145>K145,"Sim","Não") -> Não | Q145: =COUNTIFS(C:C,C145) -> 1
C146: =_xlfn.XLOOKUP(F146,'Same Seller Hist'!H:H,'Same Seller Hist'!E:E) -> 443076516 | D146: =_xlfn.XLOOKUP(F146,'Same Seller Hist'!H:H,'Same Seller Hist'!D:D) -> Bodyaction | E146: =_xlfn.XLOOKUP(F146,'Same Seller Hist'!H:H,'Same Seller Hist'!I:I) -> 7.4961818e+18 | F146: Bodyaction | G146: =_xlfn.XLOOKUP(C146,'Same Seller Hist'!E:E,'Same Seller Hist'!F:F) -> FMCG | H146: =_xlfn.IFNA(_xlfn.XLOOKUP(C146,'Shp 500'!D:D,'Shp 500'!I:I),0) -> 0 | I146: =_xlfn.IFNA(_xlfn.XLOOKUP(C146,'Shp 500'!D:D,'Shp 500'!J:J),0) -> 0 | J146: 1958.0645 | K146: 174193.55 | L146: Fastmoss 500 | M146: =IF(L146="Shp 500","Sim",IF(ISNA(_xlfn.XLOOKUP(C146,'Shp 500'!D:D,'Shp 500'!D:D)),"Não","Sim")) -> Não | N146: =IF(L146="Fastmoss 500","Sim",IF(ISNA(_xlfn.XLOOKUP(_xlfn.XLOOKUP(C146,'Same Seller Hist'!E:E,'Same Seller Hist'!H:H),'Fastmoss 500'!D:D,'Fastmoss 500'!D:D)),"Não","Sim")) -> Sim | O146: =IF(AND(M146="Sim",N146="Sim"),"Sim","Não") -> Não | P146: =IF(I146>K146,"Sim","Não") -> Não | Q146: =COUNTIFS(C:C,C146) -> 1
C147: 627750190 | D147: Pichau | E147: =_xlfn.XLOOKUP(C147,'Same Seller Hist'!E:E,'Same Seller Hist'!I:I) -> 7.4961686e+18 | F147: =_xlfn.XLOOKUP(C147,'Same Seller Hist'!E:E,'Same Seller Hist'!H:H) -> Pichau | G147: ELHA | H147: 2017.2903 | I147: 75626.787 | J147: =_xlfn.IFNA(_xlfn.XLOOKUP(F147,'Fastmoss 500'!D:D,'Fastmoss 500'!O:O),0) -> 203.22581 | K147: =_xlfn.IFNA(_xlfn.XLOOKUP(F147,'Fastmoss 500'!D:D,'Fastmoss 500'!N:N),0) -> 22596.774 | L147: Shp 500 | M147: =IF(L147="Shp 500","Sim",IF(ISNA(_xlfn.XLOOKUP(C147,'Shp 500'!D:D,'Shp 500'!D:D)),"Não","Sim")) -> Sim | N147: =IF(L147="Fastmoss 500","Sim",IF(ISNA(_xlfn.XLOOKUP(_xlfn.XLOOKUP(C147,'Same Seller Hist'!E:E,'Same Seller Hist'!H:H),'Fastmoss 500'!D:D,'Fastmoss 500'!D:D)),"Não","Sim")) -> Sim | O147: =IF(AND(M147="Sim",N147="Sim"),"Sim","Não") -> Sim | P147: =IF(I147>K147,"Sim","Não") -> Sim | Q147: =COUNTIFS(C:C,C147) -> 1
C148: 676651970 | D148: Chenjyacessorios | E148: =_xlfn.XLOOKUP(C148,'Same Seller Hist'!E:E,'Same Seller Hist'!I:I) -> 0 | F148: =_xlfn.XLOOKUP(C148,'Same Seller Hist'!E:E,'Same Seller Hist'!H:H) -> 0 | G148: CN | H148: 1106.9355 | I148: 9876.2254 | J148: =_xlfn.IFNA(_xlfn.XLOOKUP(F148,'Fastmoss 500'!D:D,'Fastmoss 500'!O:O),0) -> 0 | K148: =_xlfn.IFNA(_xlfn.XLOOKUP(F148,'Fastmoss 500'!D:D,'Fastmoss 500'!N:N),0) -> 0 | L148: Shp 500 | M148: =IF(L148="Shp 500","Sim",IF(ISNA(_xlfn.XLOOKUP(C148,'Shp 500'!D:D,'Shp 500'!D:D)),"Não","Sim")) -> Sim | N148: =IF(L148="Fastmoss 500","Sim",IF(ISNA(_xlfn.XLOOKUP(_xlfn.XLOOKUP(C148,'Same Seller Hist'!E:E,'Same Seller Hist'!H:H),'Fastmoss 500'!D:D,'Fastmoss 500'!D:D)),"Não","Sim")) -> Sim | O148: =IF(AND(M148="Sim",N148="Sim"),"Sim","Não") -> Sim | P148: =IF(I148>K148,"Sim","Não") -> Sim | Q148: =COUNTIFS(C:C,C148) -> 1
C149: =_xlfn.XLOOKUP(F149,'Same Seller Hist'!H:H,'Same Seller Hist'!E:E) -> 805674361 | D149: =_xlfn.XLOOKUP(F149,'Same Seller Hist'!H:H,'Same Seller Hist'!D:D) -> Danny Enxovais | E149: =_xlfn.XLOOKUP(F149,'Same Seller Hist'!H:H,'Same Seller Hist'!I:I) -> 7.496182e+18 | F149: Danny Enxovais | G149: =_xlfn.XLOOKUP(C149,'Same Seller Hist'!E:E,'Same Seller Hist'!F:F) -> Lifestyle | H149: =_xlfn.IFNA(_xlfn.XLOOKUP(C149,'Shp 500'!D:D,'Shp 500'!I:I),0) -> 0 | I149: =_xlfn.IFNA(_xlfn.XLOOKUP(C149,'Shp 500'!D:D,'Shp 500'!J:J),0) -> 0 | J149: 1625.8065 | K149: 41935.484 | L149: Fastmoss 500 | M149: =IF(L149="Shp 500","Sim",IF(ISNA(_xlfn.XLOOKUP(C149,'Shp 500'!D:D,'Shp 500'!D:D)),"Não","Sim")) -> Não | N149: =IF(L149="Fastmoss 500","Sim",IF(ISNA(_xlfn.XLOOKUP(_xlfn.XLOOKUP(C149,'Same Seller Hist'!E:E,'Same Seller Hist'!H:H),'Fastmoss 500'!D:D,'Fastmoss 500'!D:D)),"Não","Sim")) -> Sim | O149: =IF(AND(M149="Sim",N149="Sim"),"Sim","Não") -> Não | P149: =IF(I149>K149,"Sim","Não") -> Não | Q149: =COUNTIFS(C:C,C149) -> 1
C150: 681570887 | D150: AMOBELEZA | E150: =_xlfn.XLOOKUP(C150,'Same Seller Hist'!E:E,'Same Seller Hist'!I:I) -> 7.4961605e+18 | F150: =_xlfn.XLOOKUP(C150,'Same Seller Hist'!E:E,'Same Seller Hist'!H:H) -> AMOBELEZA | G150: FMCG | H150: 1301 | I150: 15469.541 | J150: =_xlfn.IFNA(_xlfn.XLOOKUP(F150,'Fastmoss 500'!D:D,'Fastmoss 500'!O:O),0) -> 332.25806 | K150: =_xlfn.IFNA(_xlfn.XLOOKUP(F150,'Fastmoss 500'!D:D,'Fastmoss 500'!N:N),0) -> 35483.871 | L150: Shp 500 | M150: =IF(L150="Shp 500","Sim",IF(ISNA(_xlfn.XLOOKUP(C150,'Shp 500'!D:D,'Shp 500'!D:D)),"Não","Sim")) -> Sim | N150: =IF(L150="Fastmoss 500","Sim",IF(ISNA(_xlfn.XLOOKUP(_xlfn.XLOOKUP(C150,'Same Seller Hist'!E:E,'Same Seller Hist'!H:H),'Fastmoss 500'!D:D,'Fastmoss 500'!D:D)),"Não","Sim")) -> Sim | O150: =IF(AND(M150="Sim",N150="Sim"),"Sim","Não") -> Sim | P150: =IF(I150>K150,"Sim","Não") -> Não | Q150: =COUNTIFS(C:C,C150) -> 1
C151: =_xlfn.XLOOKUP(F151,'Same Seller Hist'!H:H,'Same Seller Hist'!E:E) -> 1340867165 | D151: =_xlfn.XLOOKUP(F151,'Same Seller Hist'!H:H,'Same Seller Hist'!D:D) -> LINISO SHOP | E151: =_xlfn.XLOOKUP(F151,'Same Seller Hist'!H:H,'Same Seller Hist'!I:I) -> 7.4962125e+18 | F151: LINISO SHOP | G151: =_xlfn.XLOOKUP(C151,'Same Seller Hist'!E:E,'Same Seller Hist'!F:F) -> Fashion | H151: =_xlfn.IFNA(_xlfn.XLOOKUP(C151,'Shp 500'!D:D,'Shp 500'!I:I),0) -> 0 | I151: =_xlfn.IFNA(_xlfn.XLOOKUP(C151,'Shp 500'!D:D,'Shp 500'!J:J),0) -> 0 | J151: 1248.3871 | K151: 41935.484 | L151: Fastmoss 500 | M151: =IF(L151="Shp 500","Sim",IF(ISNA(_xlfn.XLOOKUP(C151,'Shp 500'!D:D,'Shp 500'!D:D)),"Não","Sim")) -> Não | N151: =IF(L151="Fastmoss 500","Sim",IF(ISNA(_xlfn.XLOOKUP(_xlfn.XLOOKUP(C151,'Same Seller Hist'!E:E,'Same Seller Hist'!H:H),'Fastmoss 500'!D:D,'Fastmoss 500'!D:D)),"Não","Sim")) -> Sim | O151: =IF(AND(M151="Sim",N151="Sim"),"Sim","Não") -> Não | P151: =IF(I151>K151,"Sim","Não") -> Não | Q151: =COUNTIFS(C:C,C151) -> 1
C152: =_xlfn.XLOOKUP(F152,'Same Seller Hist'!H:H,'Same Seller Hist'!E:E) -> 1504994084 | D152: =_xlfn.XLOOKUP(F152,'Same Seller Hist'!H:H,'Same Seller Hist'!D:D) -> QVida MIX | E152: =_xlfn.XLOOKUP(F152,'Same Seller Hist'!H:H,'Same Seller Hist'!I:I) -> 7.4962708e+18 | F152: QVida MIX | G152: =_xlfn.XLOOKUP(C152,'Same Seller Hist'!E:E,'Same Seller Hist'!F:F) -> Fashion | H152: =_xlfn.IFNA(_xlfn.XLOOKUP(C152,'Shp 500'!D:D,'Shp 500'!I:I),0) -> 0 | I152: =_xlfn.IFNA(_xlfn.XLOOKUP(C152,'Shp 500'!D:D,'Shp 500'!J:J),0) -> 0 | J152: 1154.8387 | K152: 32258.065 | L152: Fastmoss 500 | M152: =IF(L152="Shp 500","Sim",IF(ISNA(_xlfn.XLOOKUP(C152,'Shp 500'!D:D,'Shp 500'!D:D)),"Não","Sim")) -> Não | N152: =IF(L152="Fastmoss 500","Sim",IF(ISNA(_xlfn.XLOOKUP(_xlfn.XLOOKUP(C152,'Same Seller Hist'!E:E,'Same Seller Hist'!H:H),'Fastmoss 500'!D:D,'Fastmoss 500'!D:D)),"Não","Sim")) -> Sim | O152: =IF(AND(M152="Sim",N152="Sim"),"Sim","Não") -> Não | P152: =IF(I152>K152,"Sim","Não") -> Não | Q152: =COUNTIFS(C:C,C152) -> 1
C153: =_xlfn.XLOOKUP(F153,'Same Seller Hist'!H:H,'Same Seller Hist'!E:E) -> 283972864 | D153: =_xlfn.XLOOKUP(F153,'Same Seller Hist'!H:H,'Same Seller Hist'!D:D) -> Moderna e Slim | E153: =_xlfn.XLOOKUP(F153,'Same Seller Hist'!H:H,'Same Seller Hist'!I:I) -> 7.4961518e+18 | F153: Moderna e Slim | G153: =_xlfn.XLOOKUP(C153,'Same Seller Hist'!E:E,'Same Seller Hist'!F:F) -> Fashion | H153: =_xlfn.IFNA(_xlfn.XLOOKUP(C153,'Shp 500'!D:D,'Shp 500'!I:I),0) -> 0 | I153: =_xlfn.IFNA(_xlfn.XLOOKUP(C153,'Shp 500'!D:D,'Shp 500'!J:J),0) -> 0 | J153: 1145.1613 | K153: 51612.903 | L153: Fastmoss 500 | M153: =IF(L153="Shp 500","Sim",IF(ISNA(_xlfn.XLOOKUP(C153,'Shp 500'!D:D,'Shp 500'!D:D)),"Não","Sim")) -> Não | N153: =IF(L153="Fastmoss 500","Sim",IF(ISNA(_xlfn.XLOOKUP(_xlfn.XLOOKUP(C153,'Same Seller Hist'!E:E,'Same Seller Hist'!H:H),'Fastmoss 500'!D:D,'Fastmoss 500'!D:D)),"Não","Sim")) -> Sim | O153: =IF(AND(M153="Sim",N153="Sim"),"Sim","Não") -> Não | P153: =IF(I153>K153,"Sim","Não") -> Não | Q153: =COUNTIFS(C:C,C153) -> 1
C154: 717396632 | D154: Ankco Shop | E154: =_xlfn.XLOOKUP(C154,'Same Seller Hist'!E:E,'Same Seller Hist'!I:I) -> 7.4961532e+18 | F154: =_xlfn.XLOOKUP(C154,'Same Seller Hist'!E:E,'Same Seller Hist'!H:H) -> AnkcoShopTK | G154: CN | H154: 1742.4194 | I154: 17676.971 | J154: =_xlfn.IFNA(_xlfn.XLOOKUP(F154,'Fastmoss 500'!D:D,'Fastmoss 500'!O:O),0) -> 258.06452 | K154: =_xlfn.IFNA(_xlfn.XLOOKUP(F154,'Fastmoss 500'!D:D,'Fastmoss 500'!N:N),0) -> 14974.194 | L154: Shp 500 | M154: =IF(L154="Shp 500","Sim",IF(ISNA(_xlfn.XLOOKUP(C154,'Shp 500'!D:D,'Shp 500'!D:D)),"Não","Sim")) -> Sim | N154: =IF(L154="Fastmoss 500","Sim",IF(ISNA(_xlfn.XLOOKUP(_xlfn.XLOOKUP(C154,'Same Seller Hist'!E:E,'Same Seller Hist'!H:H),'Fastmoss 500'!D:D,'Fastmoss 500'!D:D)),"Não","Sim")) -> Sim | O154: =IF(AND(M154="Sim",N154="Sim"),"Sim","Não") -> Sim | P154: =IF(I154>K154,"Sim","Não") -> Sim | Q154: =COUNTIFS(C:C,C154) -> 1
C155: =_xlfn.XLOOKUP(F155,'Same Seller Hist'!H:H,'Same Seller Hist'!E:E) -> 452872883 | D155: =_xlfn.XLOOKUP(F155,'Same Seller Hist'!H:H,'Same Seller Hist'!D:D) -> TomiMitoo | E155: =_xlfn.XLOOKUP(F155,'Same Seller Hist'!H:H,'Same Seller Hist'!I:I) -> 7.4961645e+18 | F155: TomiMitoo | G155: =_xlfn.XLOOKUP(C155,'Same Seller Hist'!E:E,'Same Seller Hist'!F:F) -> Fashion | H155: =_xlfn.IFNA(_xlfn.XLOOKUP(C155,'Shp 500'!D:D,'Shp 500'!I:I),0) -> 0 | I155: =_xlfn.IFNA(_xlfn.XLOOKUP(C155,'Shp 500'!D:D,'Shp 500'!J:J),0) -> 0 | J155: 1103.2258 | K155: 161290.32 | L155: Fastmoss 500 | M155: =IF(L155="Shp 500","Sim",IF(ISNA(_xlfn.XLOOKUP(C155,'Shp 500'!D:D,'Shp 500'!D:D)),"Não","Sim")) -> Não | N155: =IF(L155="Fastmoss 500","Sim",IF(ISNA(_xlfn.XLOOKUP(_xlfn.XLOOKUP(C155,'Same Seller Hist'!E:E,'Same Seller Hist'!H:H),'Fastmoss 500'!D:D,'Fastmoss 500'!D:D)),"Não","Sim")) -> Sim | O155: =IF(AND(M155="Sim",N155="Sim"),"Sim","Não") -> Não | P155: =IF(I155>K155,"Sim","Não") -> Não | Q155: =COUNTIFS(C:C,C155) -> 1
C156: =_xlfn.XLOOKUP(F156,'Same Seller Hist'!H:H,'Same Seller Hist'!E:E) -> 1613760239 | D156: =_xlfn.XLOOKUP(F156,'Same Seller Hist'!H:H,'Same Seller Hist'!D:D) -> SACE LADY BR | E156: =_xlfn.XLOOKUP(F156,'Same Seller Hist'!H:H,'Same Seller Hist'!I:I) -> 7.4962591e+18 | F156: SACE LADY BR | G156: =_xlfn.XLOOKUP(C156,'Same Seller Hist'!E:E,'Same Seller Hist'!F:F) -> FMCG | H156: =_xlfn.IFNA(_xlfn.XLOOKUP(C156,'Shp 500'!D:D,'Shp 500'!I:I),0) -> 0 | I156: =_xlfn.IFNA(_xlfn.XLOOKUP(C156,'Shp 500'!D:D,'Shp 500'!J:J),0) -> 0 | J156: 1035.4839 | K156: 61290.323 | L156: Fastmoss 500 | M156: =IF(L156="Shp 500","Sim",IF(ISNA(_xlfn.XLOOKUP(C156,'Shp 500'!D:D,'Shp 500'!D:D)),"Não","Sim")) -> Não | N156: =IF(L156="Fastmoss 500","Sim",IF(ISNA(_xlfn.XLOOKUP(_xlfn.XLOOKUP(C156,'Same Seller Hist'!E:E,'Same Seller Hist'!H:H),'Fastmoss 500'!D:D,'Fastmoss 500'!D:D)),"Não","Sim")) -> Sim | O156: =IF(AND(M156="Sim",N156="Sim"),"Sim","Não") -> Não | P156: =IF(I156>K156,"Sim","Não") -> Não | Q156: =COUNTIFS(C:C,C156) -> 1
C157: 728534865 | D157: FENG . | E157: =_xlfn.XLOOKUP(C157,'Same Seller Hist'!E:E,'Same Seller Hist'!I:I) -> 7.4961617e+18 | F157: =_xlfn.XLOOKUP(C157,'Same Seller Hist'!E:E,'Same Seller Hist'!H:H) -> Feng.s | G157: CN | H157: 1769.7419 | I157: 8488.8464 | J157: =_xlfn.IFNA(_xlfn.XLOOKUP(F157,'Fastmoss 500'!D:D,'Fastmoss 500'!O:O),0) -> 745.16129 | K157: =_xlfn.IFNA(_xlfn.XLOOKUP(F157,'Fastmoss 500'!D:D,'Fastmoss 500'!N:N),0) -> 26819.355 | L157: Shp 500 | M157: =IF(L157="Shp 500","Sim",IF(ISNA(_xlfn.XLOOKUP(C157,'Shp 500'!D:D,'Shp 500'!D:D)),"Não","Sim")) -> Sim | N157: =IF(L157="Fastmoss 500","Sim",IF(ISNA(_xlfn.XLOOKUP(_xlfn.XLOOKUP(C157,'Same Seller Hist'!E:E,'Same Seller Hist'!H:H),'Fastmoss 500'!D:D,'Fastmoss 500'!D:D)),"Não","Sim")) -> Sim | O157: =IF(AND(M157="Sim",N157="Sim"),"Sim","Não") -> Sim | P157: =IF(I157>K157,"Sim","Não") -> Não | Q157: =COUNTIFS(C:C,C157) -> 1
C158: =_xlfn.XLOOKUP(F158,'Same Seller Hist'!H:H,'Same Seller Hist'!E:E) -> 969401129 | D158: =_xlfn.XLOOKUP(F158,'Same Seller Hist'!H:H,'Same Seller Hist'!D:D) -> Pink Urban | E158: =_xlfn.XLOOKUP(F158,'Same Seller Hist'!H:H,'Same Seller Hist'!I:I) -> 7.4956253e+18 | F158: Pink Urban | G158: =_xlfn.XLOOKUP(C158,'Same Seller Hist'!E:E,'Same Seller Hist'!F:F) -> Fashion | H158: =_xlfn.IFNA(_xlfn.XLOOKUP(C158,'Shp 500'!D:D,'Shp 500'!I:I),0) -> 0 | I158: =_xlfn.IFNA(_xlfn.XLOOKUP(C158,'Shp 500'!D:D,'Shp 500'!J:J),0) -> 0 | J158: 1035.4839 | K158: 58064.516 | L158: Fastmoss 500 | M158: =IF(L158="Shp 500","Sim",IF(ISNA(_xlfn.XLOOKUP(C158,'Shp 500'!D:D,'Shp 500'!D:D)),"Não","Sim")) -> Não | N158: =IF(L158="Fastmoss 500","Sim",IF(ISNA(_xlfn.XLOOKUP(_xlfn.XLOOKUP(C158,'Same Seller Hist'!E:E,'Same Seller Hist'!H:H),'Fastmoss 500'!D:D,'Fastmoss 500'!D:D)),"Não","Sim")) -> Sim | O158: =IF(AND(M158="Sim",N158="Sim"),"Sim","Não") -> Não | P158: =IF(I158>K158,"Sim","Não") -> Não | Q158: =COUNTIFS(C:C,C158) -> 1
C159: =_xlfn.XLOOKUP(F159,'Same Seller Hist'!H:H,'Same Seller Hist'!E:E) -> 999698643 | D159: =_xlfn.XLOOKUP(F159,'Same Seller Hist'!H:H,'Same Seller Hist'!D:D) -> Trevisan Calcados | E159: =_xlfn.XLOOKUP(F159,'Same Seller Hist'!H:H,'Same Seller Hist'!I:I) -> 7.496182e+18 | F159: Trevisan Calcados | G159: =_xlfn.XLOOKUP(C159,'Same Seller Hist'!E:E,'Same Seller Hist'!F:F) -> Fashion | H159: =_xlfn.IFNA(_xlfn.XLOOKUP(C159,'Shp 500'!D:D,'Shp 500'!I:I),0) -> 0 | I159: =_xlfn.IFNA(_xlfn.XLOOKUP(C159,'Shp 500'!D:D,'Shp 500'!J:J),0) -> 0 | J159: 1003.2258 | K159: 32258.065 | L159: Fastmoss 500 | M159: =IF(L159="Shp 500","Sim",IF(ISNA(_xlfn.XLOOKUP(C159,'Shp 500'!D:D,'Shp 500'!D:D)),"Não","Sim")) -> Não | N159: =IF(L159="Fastmoss 500","Sim",IF(ISNA(_xlfn.XLOOKUP(_xlfn.XLOOKUP(C159,'Same Seller Hist'!E:E,'Same Seller Hist'!H:H),'Fastmoss 500'!D:D,'Fastmoss 500'!D:D)),"Não","Sim")) -> Sim | O159: =IF(AND(M159="Sim",N159="Sim"),"Sim","Não") -> Não | P159: =IF(I159>K159,"Sim","Não") -> Não | Q159: =COUNTIFS(C:C,C159) -> 1
C160: =_xlfn.XLOOKUP(F160,'Same Seller Hist'!H:H,'Same Seller Hist'!E:E) -> 1077804858 | D160: =_xlfn.XLOOKUP(F160,'Same Seller Hist'!H:H,'Same Seller Hist'!D:D) -> Amend Cosméticos | E160: =_xlfn.XLOOKUP(F160,'Same Seller Hist'!H:H,'Same Seller Hist'!I:I) -> 7.4961615e+18 | F160: Amend Cosméticos | G160: =_xlfn.XLOOKUP(C160,'Same Seller Hist'!E:E,'Same Seller Hist'!F:F) -> FMCG | H160: =_xlfn.IFNA(_xlfn.XLOOKUP(C160,'Shp 500'!D:D,'Shp 500'!I:I),0) -> 0 | I160: =_xlfn.IFNA(_xlfn.XLOOKUP(C160,'Shp 500'!D:D,'Shp 500'!J:J),0) -> 0 | J160: 990.32258 | K160: 48387.097 | L160: Fastmoss 500 | M160: =IF(L160="Shp 500","Sim",IF(ISNA(_xlfn.XLOOKUP(C160,'Shp 500'!D:D,'Shp 500'!D:D)),"Não","Sim")) -> Não | N160: =IF(L160="Fastmoss 500","Sim",IF(ISNA(_xlfn.XLOOKUP(_xlfn.XLOOKUP(C160,'Same Seller Hist'!E:E,'Same Seller Hist'!H:H),'Fastmoss 500'!D:D,'Fastmoss 500'!D:D)),"Não","Sim")) -> Sim | O160: =IF(AND(M160="Sim",N160="Sim"),"Sim","Não") -> Não | P160: =IF(I160>K160,"Sim","Não") -> Não | Q160: =COUNTIFS(C:C,C160) -> 1
C161: 831272734 | D161: USE AD LINGERIE | E161: =_xlfn.XLOOKUP(C161,'Same Seller Hist'!E:E,'Same Seller Hist'!I:I) -> 7.494146e+18 | F161: =_xlfn.XLOOKUP(C161,'Same Seller Hist'!E:E,'Same Seller Hist'!H:H) -> AD LINGERIE | G161: Fashion | H161: 1124.3226 | I161: 7519.476 | J161: =_xlfn.IFNA(_xlfn.XLOOKUP(F161,'Fastmoss 500'!D:D,'Fastmoss 500'!O:O),0) -> 374.19355 | K161: =_xlfn.IFNA(_xlfn.XLOOKUP(F161,'Fastmoss 500'!D:D,'Fastmoss 500'!N:N),0) -> 14780.645 | L161: Shp 500 | M161: =IF(L161="Shp 500","Sim",IF(ISNA(_xlfn.XLOOKUP(C161,'Shp 500'!D:D,'Shp 500'!D:D)),"Não","Sim")) -> Sim | N161: =IF(L161="Fastmoss 500","Sim",IF(ISNA(_xlfn.XLOOKUP(_xlfn.XLOOKUP(C161,'Same Seller Hist'!E:E,'Same Seller Hist'!H:H),'Fastmoss 500'!D:D,'Fastmoss 500'!D:D)),"Não","Sim")) -> Sim | O161: =IF(AND(M161="Sim",N161="Sim"),"Sim","Não") -> Sim | P161: =IF(I161>K161,"Sim","Não") -> Não | Q161: =COUNTIFS(C:C,C161) -> 1
C162: =_xlfn.XLOOKUP(F162,'Same Seller Hist'!H:H,'Same Seller Hist'!E:E) -> 1609741857 | D162: =_xlfn.XLOOKUP(F162,'Same Seller Hist'!H:H,'Same Seller Hist'!D:D) -> Bloom Body Br | E162: =_xlfn.XLOOKUP(F162,'Same Seller Hist'!H:H,'Same Seller Hist'!I:I) -> 7.4961818e+18 | F162: Bloom Body Br | G162: =_xlfn.XLOOKUP(C162,'Same Seller Hist'!E:E,'Same Seller Hist'!F:F) -> FMCG | H162: =_xlfn.IFNA(_xlfn.XLOOKUP(C162,'Shp 500'!D:D,'Shp 500'!I:I),0) -> 0 | I162: =_xlfn.IFNA(_xlfn.XLOOKUP(C162,'Shp 500'!D:D,'Shp 500'!J:J),0) -> 0 | J162: 958.06452 | K162: 80645.161 | L162: Fastmoss 500 | M162: =IF(L162="Shp 500","Sim",IF(ISNA(_xlfn.XLOOKUP(C162,'Shp 500'!D:D,'Shp 500'!D:D)),"Não","Sim")) -> Não | N162: =IF(L162="Fastmoss 500","Sim",IF(ISNA(_xlfn.XLOOKUP(_xlfn.XLOOKUP(C162,'Same Seller Hist'!E:E,'Same Seller Hist'!H:H),'Fastmoss 500'!D:D,'Fastmoss 500'!D:D)),"Não","Sim")) -> Sim | O162: =IF(AND(M162="Sim",N162="Sim"),"Sim","Não") -> Não | P162: =IF(I162>K162,"Sim","Não") -> Não | Q162: =COUNTIFS(C:C,C162) -> 1
C163: =_xlfn.XLOOKUP(F163,'Same Seller Hist'!H:H,'Same Seller Hist'!E:E) -> 1524383764 | D163: =_xlfn.XLOOKUP(F163,'Same Seller Hist'!H:H,'Same Seller Hist'!D:D) -> KOBAC SHOP | E163: =_xlfn.XLOOKUP(F163,'Same Seller Hist'!H:H,'Same Seller Hist'!I:I) -> 7.4961832e+18 | F163: KOBAC SHOP | G163: =_xlfn.XLOOKUP(C163,'Same Seller Hist'!E:E,'Same Seller Hist'!F:F) -> 0 | H163: =_xlfn.IFNA(_xlfn.XLOOKUP(C163,'Shp 500'!D:D,'Shp 500'!I:I),0) -> 0 | I163: =_xlfn.IFNA(_xlfn.XLOOKUP(C163,'Shp 500'!D:D,'Shp 500'!J:J),0) -> 0 | J163: 954.83871 | K163: 13158.065 | L163: Fastmoss 500 | M163: =IF(L163="Shp 500","Sim",IF(ISNA(_xlfn.XLOOKUP(C163,'Shp 500'!D:D,'Shp 500'!D:D)),"Não","Sim")) -> Não | N163: =IF(L163="Fastmoss 500","Sim",IF(ISNA(_xlfn.XLOOKUP(_xlfn.XLOOKUP(C163,'Same Seller Hist'!E:E,'Same Seller Hist'!H:H),'Fastmoss 500'!D:D,'Fastmoss 500'!D:D)),"Não","Sim")) -> Sim | O163: =IF(AND(M163="Sim",N163="Sim"),"Sim","Não") -> Não | P163: =IF(I163>K163,"Sim","Não") -> Não | Q163: =COUNTIFS(C:C,C163) -> 1
C164: 874603044 | D164: SUPER CHETO | E164: =_xlfn.XLOOKUP(C164,'Same Seller Hist'!E:E,'Same Seller Hist'!I:I) -> 7.4962295e+18 | F164: =_xlfn.XLOOKUP(C164,'Same Seller Hist'!E:E,'Same Seller Hist'!H:H) -> SUPER CHETO | G164: CN | H164: 4215.5484 | I164: 37209.63 | J164: =_xlfn.IFNA(_xlfn.XLOOKUP(F164,'Fastmoss 500'!D:D,'Fastmoss 500'!O:O),0) -> 487.09677 | K164: =_xlfn.IFNA(_xlfn.XLOOKUP(F164,'Fastmoss 500'!D:D,'Fastmoss 500'!N:N),0) -> 35483.871 | L164: Shp 500 | M164: =IF(L164="Shp 500","Sim",IF(ISNA(_xlfn.XLOOKUP(C164,'Shp 500'!D:D,'Shp 500'!D:D)),"Não","Sim")) -> Sim | N164: =IF(L164="Fastmoss 500","Sim",IF(ISNA(_xlfn.XLOOKUP(_xlfn.XLOOKUP(C164,'Same Seller Hist'!E:E,'Same Seller Hist'!H:H),'Fastmoss 500'!D:D,'Fastmoss 500'!D:D)),"Não","Sim")) -> Sim | O164: =IF(AND(M164="Sim",N164="Sim"),"Sim","Não") -> Sim | P164: =IF(I164>K164,"Sim","Não") -> Sim | Q164: =COUNTIFS(C:C,C164) -> 1
C165: =_xlfn.XLOOKUP(F165,'Same Seller Hist'!H:H,'Same Seller Hist'!E:E) -> 1562142458 | D165: =_xlfn.XLOOKUP(F165,'Same Seller Hist'!H:H,'Same Seller Hist'!D:D) -> One Shop Ltda | E165: =_xlfn.XLOOKUP(F165,'Same Seller Hist'!H:H,'Same Seller Hist'!I:I) -> 7.49418e+18 | F165: One Shop Ltda | G165: =_xlfn.XLOOKUP(C165,'Same Seller Hist'!E:E,'Same Seller Hist'!F:F) -> 0 | H165: =_xlfn.IFNA(_xlfn.XLOOKUP(C165,'Shp 500'!D:D,'Shp 500'!I:I),0) -> 0 | I165: =_xlfn.IFNA(_xlfn.XLOOKUP(C165,'Shp 500'!D:D,'Shp 500'!J:J),0) -> 0 | J165: 903.22581 | K165: 35483.871 | L165: Fastmoss 500 | M165: =IF(L165="Shp 500","Sim",IF(ISNA(_xlfn.XLOOKUP(C165,'Shp 500'!D:D,'Shp 500'!D:D)),"Não","Sim")) -> Não | N165: =IF(L165="Fastmoss 500","Sim",IF(ISNA(_xlfn.XLOOKUP(_xlfn.XLOOKUP(C165,'Same Seller Hist'!E:E,'Same Seller Hist'!H:H),'Fastmoss 500'!D:D,'Fastmoss 500'!D:D)),"Não","Sim")) -> Sim | O165: =IF(AND(M165="Sim",N165="Sim"),"Sim","Não") -> Não | P165: =IF(I165>K165,"Sim","Não") -> Não | Q165: =COUNTIFS(C:C,C165) -> 1
...

Sheet Analysis Table dup
B3: TABELA DE SUPORTE PARA ANÁLISE
C7: shop_id_shp | D7: shop_name_shp | E7: shop_id_tts | F7: shop_name_tts | G7: cluster | H7: net_ado_shp | I7: net_adnmv_usd_shp | J7: net_ado_tts | K7: net_adnmv_usd_tts | L7: source | M7: top_at_shp | N7: top_at_tts | O7: top_at_both | P7: bigger_at_shp | Q7: duplicates
C8: 291174073 | D8: ZSZ_Official Store | E8: =_xlfn.XLOOKUP(C8,'Same Seller Hist'!E:E,'Same Seller Hist'!I:I) -> 7.4961635e+18 | F8: =_xlfn.XLOOKUP(C8,'Same Seller Hist'!E:E,'Same Seller Hist'!H:H) -> ZSZ BR | G8: CN | H8: 1622 | I8: 9436.935 | J8: =_xlfn.IFNA(_xlfn.XLOOKUP(F8,'Fastmoss 500'!D:D,'Fastmoss 500'!O:O),0) -> 700 | K8: =_xlfn.IFNA(_xlfn.XLOOKUP(F8,'Fastmoss 500'!D:D,'Fastmoss 500'!N:N),0) -> 14158.065 | L8: Shp 500 | M8: =IF(L8="Shp 500","Sim",IF(ISNA(_xlfn.XLOOKUP(C8,'Shp 500'!D:D,'Shp 500'!D:D)),"Não","Sim")) -> Sim | N8: =IF(L8="Fastmoss 500","Sim",IF(ISNA(_xlfn.XLOOKUP(_xlfn.XLOOKUP(C8,'Same Seller Hist'!E:E,'Same Seller Hist'!H:H),'Fastmoss 500'!D:D,'Fastmoss 500'!D:D)),"Não","Sim")) -> Sim | O8: =IF(AND(M8="Sim",N8="Sim"),"Sim","Não") -> Sim | P8: =IF(I8>K8,"Sim","Não") -> Não | Q8: =COUNTIFS(C:C,C8) -> 2
C9: =_xlfn.XLOOKUP(F9,'Same Seller Hist'!H:H,'Same Seller Hist'!E:E) -> 291174073 | D9: =_xlfn.XLOOKUP(F9,'Same Seller Hist'!H:H,'Same Seller Hist'!D:D) -> ZSZ BR | E9: =_xlfn.XLOOKUP(F9,'Same Seller Hist'!H:H,'Same Seller Hist'!I:I) -> 7.4961635e+18 | F9: ZSZ BR | G9: =_xlfn.XLOOKUP(C9,'Same Seller Hist'!E:E,'Same Seller Hist'!F:F) -> Lifestyle | H9: =_xlfn.IFNA(_xlfn.XLOOKUP(C9,'Shp 500'!D:D,'Shp 500'!I:I),0) -> 1622 | I9: =_xlfn.IFNA(_xlfn.XLOOKUP(C9,'Shp 500'!D:D,'Shp 500'!J:J),0) -> 9436.935 | J9: 700 | K9: 14158.065 | L9: Fastmoss 500 | M9: =IF(L9="Shp 500","Sim",IF(ISNA(_xlfn.XLOOKUP(C9,'Shp 500'!D:D,'Shp 500'!D:D)),"Não","Sim")) -> Sim | N9: =IF(L9="Fastmoss 500","Sim",IF(ISNA(_xlfn.XLOOKUP(_xlfn.XLOOKUP(C9,'Same Seller Hist'!E:E,'Same Seller Hist'!H:H),'Fastmoss 500'!D:D,'Fastmoss 500'!D:D)),"Não","Sim")) -> Sim | O9: =IF(AND(M9="Sim",N9="Sim"),"Sim","Não") -> Sim | P9: =IF(I9>K9,"Sim","Não") -> Não | Q9: =COUNTIFS(C:C,C9) -> 2
C10: 552896405 | D10: Casa_Completa_Enxovais | E10: =_xlfn.XLOOKUP(C10,'Same Seller Hist'!E:E,'Same Seller Hist'!I:I) -> 7.49626e+18 | F10: =_xlfn.XLOOKUP(C10,'Same Seller Hist'!E:E,'Same Seller Hist'!H:H) -> Casa Completa Enxovais | G10: Lifestyle | H10: 5043.8387 | I10: 53289.304 | J10: =_xlfn.IFNA(_xlfn.XLOOKUP(F10,'Fastmoss 500'!D:D,'Fastmoss 500'!O:O),0) -> 0 | K10: =_xlfn.IFNA(_xlfn.XLOOKUP(F10,'Fastmoss 500'!D:D,'Fastmoss 500'!N:N),0) -> 0 | L10: Shp 500 | M10: =IF(L10="Shp 500","Sim",IF(ISNA(_xlfn.XLOOKUP(C10,'Shp 500'!D:D,'Shp 500'!D:D)),"Não","Sim")) -> Sim | N10: =IF(L10="Fastmoss 500","Sim",IF(ISNA(_xlfn.XLOOKUP(_xlfn.XLOOKUP(C10,'Same Seller Hist'!E:E,'Same Seller Hist'!H:H),'Fastmoss 500'!D:D,'Fastmoss 500'!D:D)),"Não","Sim")) -> Não | O10: =IF(AND(M10="Sim",N10="Sim"),"Sim","Não") -> Não | P10: =IF(I10>K10,"Sim","Não") -> Sim | Q10: =COUNTIFS(C:C,C10) -> 1
C11: 974102638 | D11: Loja 128 | E11: =_xlfn.XLOOKUP(C11,'Same Seller Hist'!E:E,'Same Seller Hist'!I:I) -> 7.4962283e+18 | F11: =_xlfn.XLOOKUP(C11,'Same Seller Hist'!E:E,'Same Seller Hist'!H:H) -> blueepulse | G11: CN | H11: 4870.1613 | I11: 49065.871 | J11: =_xlfn.IFNA(_xlfn.XLOOKUP(F11,'Fastmoss 500'!D:D,'Fastmoss 500'!O:O),0) -> 0 | K11: =_xlfn.IFNA(_xlfn.XLOOKUP(F11,'Fastmoss 500'!D:D,'Fastmoss 500'!N:N),0) -> 0 | L11: Shp 500 | M11: =IF(L11="Shp 500","Sim",IF(ISNA(_xlfn.XLOOKUP(C11,'Shp 500'!D:D,'Shp 500'!D:D)),"Não","Sim")) -> Sim | N11: =IF(L11="Fastmoss 500","Sim",IF(ISNA(_xlfn.XLOOKUP(_xlfn.XLOOKUP(C11,'Same Seller Hist'!E:E,'Same Seller Hist'!H:H),'Fastmoss 500'!D:D,'Fastmoss 500'!D:D)),"Não","Sim")) -> Não | O11: =IF(AND(M11="Sim",N11="Sim"),"Sim","Não") -> Não | P11: =IF(I11>K11,"Sim","Não") -> Sim | Q11: =COUNTIFS(C:C,C11) -> 1
C12: 362859393 | D12: ALFA MERCEARIA.BR | E12: =_xlfn.XLOOKUP(C12,'Same Seller Hist'!E:E,'Same Seller Hist'!I:I) -> 7.4961597e+18 | F12: =_xlfn.XLOOKUP(C12,'Same Seller Hist'!E:E,'Same Seller Hist'!H:H) -> ALFA SHOP.BR | G12: CN | H12: 4604.9355 | I12: 14928.731 | J12: =_xlfn.IFNA(_xlfn.XLOOKUP(F12,'Fastmoss 500'!D:D,'Fastmoss 500'!O:O),0) -> 0 | K12: =_xlfn.IFNA(_xlfn.XLOOKUP(F12,'Fastmoss 500'!D:D,'Fastmoss 500'!N:N),0) -> 0 | L12: Shp 500 | M12: =IF(L12="Shp 500","Sim",IF(ISNA(_xlfn.XLOOKUP(C12,'Shp 500'!D:D,'Shp 500'!D:D)),"Não","Sim")) -> Sim | N12: =IF(L12="Fastmoss 500","Sim",IF(ISNA(_xlfn.XLOOKUP(_xlfn.XLOOKUP(C12,'Same Seller Hist'!E:E,'Same Seller Hist'!H:H),'Fastmoss 500'!D:D,'Fastmoss 500'!D:D)),"Não","Sim")) -> Não | O12: =IF(AND(M12="Sim",N12="Sim"),"Sim","Não") -> Não | P12: =IF(I12>K12,"Sim","Não") -> Sim | Q12: =COUNTIFS(C:C,C12) -> 1
C13: 1045085918 | D13: Droga Clara | E13: =_xlfn.XLOOKUP(C13,'Same Seller Hist'!E:E,'Same Seller Hist'!I:I) -> 7.4941815e+18 | F13: =_xlfn.XLOOKUP(C13,'Same Seller Hist'!E:E,'Same Seller Hist'!H:H) -> YUMI CELL BR | G13: FMCG | H13: 4299.4839 | I13: 22995.675 | J13: =_xlfn.IFNA(_xlfn.XLOOKUP(F13,'Fastmoss 500'!D:D,'Fastmoss 500'!O:O),0) -> 235.48387 | K13: =_xlfn.IFNA(_xlfn.XLOOKUP(F13,'Fastmoss 500'!D:D,'Fastmoss 500'!N:N),0) -> 17706.452 | L13: Shp 500 | M13: =IF(L13="Shp 500","Sim",IF(ISNA(_xlfn.XLOOKUP(C13,'Shp 500'!D:D,'Shp 500'!D:D)),"Não","Sim")) -> Sim | N13: =IF(L13="Fastmoss 500","Sim",IF(ISNA(_xlfn.XLOOKUP(_xlfn.XLOOKUP(C13,'Same Seller Hist'!E:E,'Same Seller Hist'!H:H),'Fastmoss 500'!D:D,'Fastmoss 500'!D:D)),"Não","Sim")) -> Sim | O13: =IF(AND(M13="Sim",N13="Sim"),"Sim","Não") -> Sim | P13: =IF(I13>K13,"Sim","Não") -> Sim | Q13: =COUNTIFS(C:C,C13) -> 1
C14: 296363855 | D14: CasaLauraEnxovais | E14: =_xlfn.XLOOKUP(C14,'Same Seller Hist'!E:E,'Same Seller Hist'!I:I) -> 7.4955619e+18 | F14: =_xlfn.XLOOKUP(C14,'Same Seller Hist'!E:E,'Same Seller Hist'!H:H) -> Casa Laura Enxovais | G14: Lifestyle | H14: 1873.9355 | I14: 15155.613 | J14: =_xlfn.IFNA(_xlfn.XLOOKUP(F14,'Fastmoss 500'!D:D,'Fastmoss 500'!O:O),0) -> 280.64516 | K14: =_xlfn.IFNA(_xlfn.XLOOKUP(F14,'Fastmoss 500'!D:D,'Fastmoss 500'!N:N),0) -> 16445.161 | L14: Shp 500 | M14: =IF(L14="Shp 500","Sim",IF(ISNA(_xlfn.XLOOKUP(C14,'Shp 500'!D:D,'Shp 500'!D:D)),"Não","Sim")) -> Sim | N14: =IF(L14="Fastmoss 500","Sim",IF(ISNA(_xlfn.XLOOKUP(_xlfn.XLOOKUP(C14,'Same Seller Hist'!E:E,'Same Seller Hist'!H:H),'Fastmoss 500'!D:D,'Fastmoss 500'!D:D)),"Não","Sim")) -> Sim | O14: =IF(AND(M14="Sim",N14="Sim"),"Sim","Não") -> Sim | P14: =IF(I14>K14,"Sim","Não") -> Não | Q14: =COUNTIFS(C:C,C14) -> 2
C15: =_xlfn.XLOOKUP(F15,'Same Seller Hist'!H:H,'Same Seller Hist'!E:E) -> 296363855 | D15: =_xlfn.XLOOKUP(F15,'Same Seller Hist'!H:H,'Same Seller Hist'!D:D) -> Casa Laura Enxovais | E15: =_xlfn.XLOOKUP(F15,'Same Seller Hist'!H:H,'Same Seller Hist'!I:I) -> 7.4955619e+18 | F15: Casa Laura Enxovais | G15: =_xlfn.XLOOKUP(C15,'Same Seller Hist'!E:E,'Same Seller Hist'!F:F) -> Lifestyle | H15: =_xlfn.IFNA(_xlfn.XLOOKUP(C15,'Shp 500'!D:D,'Shp 500'!I:I),0) -> 1873.9355 | I15: =_xlfn.IFNA(_xlfn.XLOOKUP(C15,'Shp 500'!D:D,'Shp 500'!J:J),0) -> 15155.613 | J15: 280.64516 | K15: 16445.161 | L15: Fastmoss 500 | M15: =IF(L15="Shp 500","Sim",IF(ISNA(_xlfn.XLOOKUP(C15,'Shp 500'!D:D,'Shp 500'!D:D)),"Não","Sim")) -> Sim | N15: =IF(L15="Fastmoss 500","Sim",IF(ISNA(_xlfn.XLOOKUP(_xlfn.XLOOKUP(C15,'Same Seller Hist'!E:E,'Same Seller Hist'!H:H),'Fastmoss 500'!D:D,'Fastmoss 500'!D:D)),"Não","Sim")) -> Sim | O15: =IF(AND(M15="Sim",N15="Sim"),"Sim","Não") -> Sim | P15: =IF(I15>K15,"Sim","Não") -> Não | Q15: =COUNTIFS(C:C,C15) -> 2
C16: 872424585 | D16: Mega TechStore | E16: =_xlfn.XLOOKUP(C16,'Same Seller Hist'!E:E,'Same Seller Hist'!I:I) -> 7.4961817e+18 | F16: =_xlfn.XLOOKUP(C16,'Same Seller Hist'!E:E,'Same Seller Hist'!H:H) -> mega tech store | G16: CN | H16: 3866.0645 | I16: 31272.972 | J16: =_xlfn.IFNA(_xlfn.XLOOKUP(F16,'Fastmoss 500'!D:D,'Fastmoss 500'!O:O),0) -> 0 | K16: =_xlfn.IFNA(_xlfn.XLOOKUP(F16,'Fastmoss 500'!D:D,'Fastmoss 500'!N:N),0) -> 0 | L16: Shp 500 | M16: =IF(L16="Shp 500","Sim",IF(ISNA(_xlfn.XLOOKUP(C16,'Shp 500'!D:D,'Shp 500'!D:D)),"Não","Sim")) -> Sim | N16: =IF(L16="Fastmoss 500","Sim",IF(ISNA(_xlfn.XLOOKUP(_xlfn.XLOOKUP(C16,'Same Seller Hist'!E:E,'Same Seller Hist'!H:H),'Fastmoss 500'!D:D,'Fastmoss 500'!D:D)),"Não","Sim")) -> Não | O16: =IF(AND(M16="Sim",N16="Sim"),"Sim","Não") -> Não | P16: =IF(I16>K16,"Sim","Não") -> Sim | Q16: =COUNTIFS(C:C,C16) -> 1
C17: 643719371 | D17: NEWCOOL | E17: =_xlfn.XLOOKUP(C17,'Same Seller Hist'!E:E,'Same Seller Hist'!I:I) -> 7.496184e+18 | F17: =_xlfn.XLOOKUP(C17,'Same Seller Hist'!E:E,'Same Seller Hist'!H:H) -> NEWCOOL.BR | G17: CN | H17: 3826.9355 | I17: 19013.021 | J17: =_xlfn.IFNA(_xlfn.XLOOKUP(F17,'Fastmoss 500'!D:D,'Fastmoss 500'!O:O),0) -> 0 | K17: =_xlfn.IFNA(_xlfn.XLOOKUP(F17,'Fastmoss 500'!D:D,'Fastmoss 500'!N:N),0) -> 0 | L17: Shp 500 | M17: =IF(L17="Shp 500","Sim",IF(ISNA(_xlfn.XLOOKUP(C17,'Shp 500'!D:D,'Shp 500'!D:D)),"Não","Sim")) -> Sim | N17: =IF(L17="Fastmoss 500","Sim",IF(ISNA(_xlfn.XLOOKUP(_xlfn.XLOOKUP(C17,'Same Seller Hist'!E:E,'Same Seller Hist'!H:H),'Fastmoss 500'!D:D,'Fastmoss 500'!D:D)),"Não","Sim")) -> Não | O17: =IF(AND(M17="Sim",N17="Sim"),"Sim","Não") -> Não | P17: =IF(I17>K17,"Sim","Não") -> Sim | Q17: =COUNTIFS(C:C,C17) -> 1
C18: 299222557 | D18: RIven Bazar | E18: =_xlfn.XLOOKUP(C18,'Same Seller Hist'!E:E,'Same Seller Hist'!I:I) -> 7.4961792e+18 | F18: =_xlfn.XLOOKUP(C18,'Same Seller Hist'!E:E,'Same Seller Hist'!H:H) -> RIVEN BAZAR | G18: CN | H18: 2540.1613 | I18: 9178.8417 | J18: =_xlfn.IFNA(_xlfn.XLOOKUP(F18,'Fastmoss 500'!D:D,'Fastmoss 500'!O:O),0) -> 251.6129 | K18: =_xlfn.IFNA(_xlfn.XLOOKUP(F18,'Fastmoss 500'!D:D,'Fastmoss 500'!N:N),0) -> 10303.226 | L18: Shp 500 | M18: =IF(L18="Shp 500","Sim",IF(ISNA(_xlfn.XLOOKUP(C18,'Shp 500'!D:D,'Shp 500'!D:D)),"Não","Sim")) -> Sim | N18: =IF(L18="Fastmoss 500","Sim",IF(ISNA(_xlfn.XLOOKUP(_xlfn.XLOOKUP(C18,'Same Seller Hist'!E:E,'Same Seller Hist'!H:H),'Fastmoss 500'!D:D,'Fastmoss 500'!D:D)),"Não","Sim")) -> Sim | O18: =IF(AND(M18="Sim",N18="Sim"),"Sim","Não") -> Sim | P18: =IF(I18>K18,"Sim","Não") -> Não | Q18: =COUNTIFS(C:C,C18) -> 2
C19: 1064041485 | D19: LuxeElectra | E19: =_xlfn.XLOOKUP(C19,'Same Seller Hist'!E:E,'Same Seller Hist'!I:I) -> 7.4961859e+18 | F19: =_xlfn.XLOOKUP(C19,'Same Seller Hist'!E:E,'Same Seller Hist'!H:H) -> luxeelectra | G19: CN | H19: 3451.0968 | I19: 33941.769 | J19: =_xlfn.IFNA(_xlfn.XLOOKUP(F19,'Fastmoss 500'!D:D,'Fastmoss 500'!O:O),0) -> 0 | K19: =_xlfn.IFNA(_xlfn.XLOOKUP(F19,'Fastmoss 500'!D:D,'Fastmoss 500'!N:N),0) -> 0 | L19: Shp 500 | M19: =IF(L19="Shp 500","Sim",IF(ISNA(_xlfn.XLOOKUP(C19,'Shp 500'!D:D,'Shp 500'!D:D)),"Não","Sim")) -> Sim | N19: =IF(L19="Fastmoss 500","Sim",IF(ISNA(_xlfn.XLOOKUP(_xlfn.XLOOKUP(C19,'Same Seller Hist'!E:E,'Same Seller Hist'!H:H),'Fastmoss 500'!D:D,'Fastmoss 500'!D:D)),"Não","Sim")) -> Não | O19: =IF(AND(M19="Sim",N19="Sim"),"Sim","Não") -> Não | P19: =IF(I19>K19,"Sim","Não") -> Sim | Q19: =COUNTIFS(C:C,C19) -> 1
C20: 341167297 | D20: Poloinfantil.store | E20: =_xlfn.XLOOKUP(C20,'Same Seller Hist'!E:E,'Same Seller Hist'!I:I) -> 0 | F20: =_xlfn.XLOOKUP(C20,'Same Seller Hist'!E:E,'Same Seller Hist'!H:H) -> 0 | G20: Fashion | H20: 3346.871 | I20: 37236.535 | J20: =_xlfn.IFNA(_xlfn.XLOOKUP(F20,'Fastmoss 500'!D:D,'Fastmoss 500'!O:O),0) -> 0 | K20: =_xlfn.IFNA(_xlfn.XLOOKUP(F20,'Fastmoss 500'!D:D,'Fastmoss 500'!N:N),0) -> 0 | L20: Shp 500 | M20: =IF(L20="Shp 500","Sim",IF(ISNA(_xlfn.XLOOKUP(C20,'Shp 500'!D:D,'Shp 500'!D:D)),"Não","Sim")) -> Sim | N20: =IF(L20="Fastmoss 500","Sim",IF(ISNA(_xlfn.XLOOKUP(_xlfn.XLOOKUP(C20,'Same Seller Hist'!E:E,'Same Seller Hist'!H:H),'Fastmoss 500'!D:D,'Fastmoss 500'!D:D)),"Não","Sim")) -> Não | O20: =IF(AND(M20="Sim",N20="Sim"),"Sim","Não") -> Não | P20: =IF(I20>K20,"Sim","Não") -> Sim | Q20: =COUNTIFS(C:C,C20) -> 1
C21: 313660590 | D21: Nosso Lar Enxovais | E21: =_xlfn.XLOOKUP(C21,'Same Seller Hist'!E:E,'Same Seller Hist'!I:I) -> 7.4940983e+18 | F21: =_xlfn.XLOOKUP(C21,'Same Seller Hist'!E:E,'Same Seller Hist'!H:H) -> Nosso Lar Enxovais | G21: Lifestyle | H21: 3313.3226 | I21: 29155.732 | J21: =_xlfn.IFNA(_xlfn.XLOOKUP(F21,'Fastmoss 500'!D:D,'Fastmoss 500'!O:O),0) -> 0 | K21: =_xlfn.IFNA(_xlfn.XLOOKUP(F21,'Fastmoss 500'!D:D,'Fastmoss 500'!N:N),0) -> 0 | L21: Shp 500 | M21: =IF(L21="Shp 500","Sim",IF(ISNA(_xlfn.XLOOKUP(C21,'Shp 500'!D:D,'Shp 500'!D:D)),"Não","Sim")) -> Sim | N21: =IF(L21="Fastmoss 500","Sim",IF(ISNA(_xlfn.XLOOKUP(_xlfn.XLOOKUP(C21,'Same Seller Hist'!E:E,'Same Seller Hist'!H:H),'Fastmoss 500'!D:D,'Fastmoss 500'!D:D)),"Não","Sim")) -> Não | O21: =IF(AND(M21="Sim",N21="Sim"),"Sim","Não") -> Não | P21: =IF(I21>K21,"Sim","Não") -> Sim | Q21: =COUNTIFS(C:C,C21) -> 1
C22: =_xlfn.XLOOKUP(F22,'Same Seller Hist'!H:H,'Same Seller Hist'!E:E) -> 299222557 | D22: =_xlfn.XLOOKUP(F22,'Same Seller Hist'!H:H,'Same Seller Hist'!D:D) -> RIVEN BAZAR | E22: =_xlfn.XLOOKUP(F22,'Same Seller Hist'!H:H,'Same Seller Hist'!I:I) -> 7.4961792e+18 | F22: RIVEN BAZAR | G22: =_xlfn.XLOOKUP(C22,'Same Seller Hist'!E:E,'Same Seller Hist'!F:F) -> FMCG | H22: =_xlfn.IFNA(_xlfn.XLOOKUP(C22,'Shp 500'!D:D,'Shp 500'!I:I),0) -> 2540.1613 | I22: =_xlfn.IFNA(_xlfn.XLOOKUP(C22,'Shp 500'!D:D,'Shp 500'!J:J),0) -> 9178.8417 | J22: 251.6129 | K22: 10303.226 | L22: Fastmoss 500 | M22: =IF(L22="Shp 500","Sim",IF(ISNA(_xlfn.XLOOKUP(C22,'Shp 500'!D:D,'Shp 500'!D:D)),"Não","Sim")) -> Sim | N22: =IF(L22="Fastmoss 500","Sim",IF(ISNA(_xlfn.XLOOKUP(_xlfn.XLOOKUP(C22,'Same Seller Hist'!E:E,'Same Seller Hist'!H:H),'Fastmoss 500'!D:D,'Fastmoss 500'!D:D)),"Não","Sim")) -> Sim | O22: =IF(AND(M22="Sim",N22="Sim"),"Sim","Não") -> Sim | P22: =IF(I22>K22,"Sim","Não") -> Não | Q22: =COUNTIFS(C:C,C22) -> 2
C23: 313984108 | D23: CASA NOVA ENXOVAIS E DECORAÇÃO | E23: =_xlfn.XLOOKUP(C23,'Same Seller Hist'!E:E,'Same Seller Hist'!I:I) -> 7.4940883e+18 | F23: =_xlfn.XLOOKUP(C23,'Same Seller Hist'!E:E,'Same Seller Hist'!H:H) -> Casa Nova Enxovais e Decoração | G23: Lifestyle | H23: 2282.8387 | I23: 18438.426 | J23: =_xlfn.IFNA(_xlfn.XLOOKUP(F23,'Fastmoss 500'!D:D,'Fastmoss 500'!O:O),0) -> 383.87097 | K23: =_xlfn.IFNA(_xlfn.XLOOKUP(F23,'Fastmoss 500'!D:D,'Fastmoss 500'!N:N),0) -> 9980.6452 | L23: Shp 500 | M23: =IF(L23="Shp 500","Sim",IF(ISNA(_xlfn.XLOOKUP(C23,'Shp 500'!D:D,'Shp 500'!D:D)),"Não","Sim")) -> Sim | N23: =IF(L23="Fastmoss 500","Sim",IF(ISNA(_xlfn.XLOOKUP(_xlfn.XLOOKUP(C23,'Same Seller Hist'!E:E,'Same Seller Hist'!H:H),'Fastmoss 500'!D:D,'Fastmoss 500'!D:D)),"Não","Sim")) -> Sim | O23: =IF(AND(M23="Sim",N23="Sim"),"Sim","Não") -> Sim | P23: =IF(I23>K23,"Sim","Não") -> Sim | Q23: =COUNTIFS(C:C,C23) -> 2
C24: =_xlfn.XLOOKUP(F24,'Same Seller Hist'!H:H,'Same Seller Hist'!E:E) -> 313984108 | D24: =_xlfn.XLOOKUP(F24,'Same Seller Hist'!H:H,'Same Seller Hist'!D:D) -> Casa Nova Enxovais e Decoração | E24: =_xlfn.XLOOKUP(F24,'Same Seller Hist'!H:H,'Same Seller Hist'!I:I) -> 7.4940883e+18 | F24: Casa Nova Enxovais e Decoração | G24: =_xlfn.XLOOKUP(C24,'Same Seller Hist'!E:E,'Same Seller Hist'!F:F) -> Lifestyle | H24: =_xlfn.IFNA(_xlfn.XLOOKUP(C24,'Shp 500'!D:D,'Shp 500'!I:I),0) -> 2282.8387 | I24: =_xlfn.IFNA(_xlfn.XLOOKUP(C24,'Shp 500'!D:D,'Shp 500'!J:J),0) -> 18438.426 | J24: 383.87097 | K24: 9980.6452 | L24: Fastmoss 500 | M24: =IF(L24="Shp 500","Sim",IF(ISNA(_xlfn.XLOOKUP(C24,'Shp 500'!D:D,'Shp 500'!D:D)),"Não","Sim")) -> Sim | N24: =IF(L24="Fastmoss 500","Sim",IF(ISNA(_xlfn.XLOOKUP(_xlfn.XLOOKUP(C24,'Same Seller Hist'!E:E,'Same Seller Hist'!H:H),'Fastmoss 500'!D:D,'Fastmoss 500'!D:D)),"Não","Sim")) -> Sim | O24: =IF(AND(M24="Sim",N24="Sim"),"Sim","Não") -> Sim | P24: =IF(I24>K24,"Sim","Não") -> Sim | Q24: =COUNTIFS(C:C,C24) -> 2
C25: 343246764 | D25: Zyoou Market | E25: =_xlfn.XLOOKUP(C25,'Same Seller Hist'!E:E,'Same Seller Hist'!I:I) -> 7.4961625e+18 | F25: =_xlfn.XLOOKUP(C25,'Same Seller Hist'!E:E,'Same Seller Hist'!H:H) -> Zyoou Market | G25: CN | H25: 3018.7419 | I25: 12152.887 | J25: =_xlfn.IFNA(_xlfn.XLOOKUP(F25,'Fastmoss 500'!D:D,'Fastmoss 500'!O:O),0) -> 0 | K25: =_xlfn.IFNA(_xlfn.XLOOKUP(F25,'Fastmoss 500'!D:D,'Fastmoss 500'!N:N),0) -> 0 | L25: Shp 500 | M25: =IF(L25="Shp 500","Sim",IF(ISNA(_xlfn.XLOOKUP(C25,'Shp 500'!D:D,'Shp 500'!D:D)),"Não","Sim")) -> Sim | N25: =IF(L25="Fastmoss 500","Sim",IF(ISNA(_xlfn.XLOOKUP(_xlfn.XLOOKUP(C25,'Same Seller Hist'!E:E,'Same Seller Hist'!H:H),'Fastmoss 500'!D:D,'Fastmoss 500'!D:D)),"Não","Sim")) -> Não | O25: =IF(AND(M25="Sim",N25="Sim"),"Sim","Não") -> Não | P25: =IF(I25>K25,"Sim","Não") -> Sim | Q25: =COUNTIFS(C:C,C25) -> 1
C26: 418205294 | D26: ANA 1108 | E26: =_xlfn.XLOOKUP(C26,'Same Seller Hist'!E:E,'Same Seller Hist'!I:I) -> 7.4961473e+18 | F26: =_xlfn.XLOOKUP(C26,'Same Seller Hist'!E:E,'Same Seller Hist'!H:H) -> ANA1108 SHOP | G26: CN | H26: 3015.129 | I26: 11080.647 | J26: =_xlfn.IFNA(_xlfn.XLOOKUP(F26,'Fastmoss 500'!D:D,'Fastmoss 500'!O:O),0) -> 0 | K26: =_xlfn.IFNA(_xlfn.XLOOKUP(F26,'Fastmoss 500'!D:D,'Fastmoss 500'!N:N),0) -> 0 | L26: Shp 500 | M26: =IF(L26="Shp 500","Sim",IF(ISNA(_xlfn.XLOOKUP(C26,'Shp 500'!D:D,'Shp 500'!D:D)),"Não","Sim")) -> Sim | N26: =IF(L26="Fastmoss 500","Sim",IF(ISNA(_xlfn.XLOOKUP(_xlfn.XLOOKUP(C26,'Same Seller Hist'!E:E,'Same Seller Hist'!H:H),'Fastmoss 500'!D:D,'Fastmoss 500'!D:D)),"Não","Sim")) -> Não | O26: =IF(AND(M26="Sim",N26="Sim"),"Sim","Não") -> Não | P26: =IF(I26>K26,"Sim","Não") -> Sim | Q26: =COUNTIFS(C:C,C26) -> 1
C27: 300779622 | D27: Icasa Ibitinga | E27: =_xlfn.XLOOKUP(C27,'Same Seller Hist'!E:E,'Same Seller Hist'!I:I) -> 7.4962023e+18 | F27: =_xlfn.XLOOKUP(C27,'Same Seller Hist'!E:E,'Same Seller Hist'!H:H) -> Icasa Ibitinga | G27: Lifestyle | H27: 2956.2903 | I27: 25985.607 | J27: =_xlfn.IFNA(_xlfn.XLOOKUP(F27,'Fastmoss 500'!D:D,'Fastmoss 500'!O:O),0) -> 0 | K27: =_xlfn.IFNA(_xlfn.XLOOKUP(F27,'Fastmoss 500'!D:D,'Fastmoss 500'!N:N),0) -> 0 | L27: Shp 500 | M27: =IF(L27="Shp 500","Sim",IF(ISNA(_xlfn.XLOOKUP(C27,'Shp 500'!D:D,'Shp 500'!D:D)),"Não","Sim")) -> Sim | N27: =IF(L27="Fastmoss 500","Sim",IF(ISNA(_xlfn.XLOOKUP(_xlfn.XLOOKUP(C27,'Same Seller Hist'!E:E,'Same Seller Hist'!H:H),'Fastmoss 500'!D:D,'Fastmoss 500'!D:D)),"Não","Sim")) -> Não | O27: =IF(AND(M27="Sim",N27="Sim"),"Sim","Não") -> Não | P27: =IF(I27>K27,"Sim","Não") -> Sim | Q27: =COUNTIFS(C:C,C27) -> 1
C28: 394731864 | D28: EvaMia | E28: =_xlfn.XLOOKUP(C28,'Same Seller Hist'!E:E,'Same Seller Hist'!I:I) -> 7.4961625e+18 | F28: =_xlfn.XLOOKUP(C28,'Same Seller Hist'!E:E,'Same Seller Hist'!H:H) -> Evamia 21 | G28: CN | H28: 2890.5484 | I28: 11832.645 | J28: =_xlfn.IFNA(_xlfn.XLOOKUP(F28,'Fastmoss 500'!D:D,'Fastmoss 500'!O:O),0) -> 0 | K28: =_xlfn.IFNA(_xlfn.XLOOKUP(F28,'Fastmoss 500'!D:D,'Fastmoss 500'!N:N),0) -> 0 | L28: Shp 500 | M28: =IF(L28="Shp 500","Sim",IF(ISNA(_xlfn.XLOOKUP(C28,'Shp 500'!D:D,'Shp 500'!D:D)),"Não","Sim")) -> Sim | N28: =IF(L28="Fastmoss 500","Sim",IF(ISNA(_xlfn.XLOOKUP(_xlfn.XLOOKUP(C28,'Same Seller Hist'!E:E,'Same Seller Hist'!H:H),'Fastmoss 500'!D:D,'Fastmoss 500'!D:D)),"Não","Sim")) -> Não | O28: =IF(AND(M28="Sim",N28="Sim"),"Sim","Não") -> Não | P28: =IF(I28>K28,"Sim","Não") -> Sim | Q28: =COUNTIFS(C:C,C28) -> 1
C29: 325008325 | D29: Na Web Group De Marcas | E29: =_xlfn.XLOOKUP(C29,'Same Seller Hist'!E:E,'Same Seller Hist'!I:I) -> 0 | F29: =_xlfn.XLOOKUP(C29,'Same Seller Hist'!E:E,'Same Seller Hist'!H:H) -> 0 | G29: Lifestyle | H29: 1795.6129 | I29: 32107.84 | J29: =_xlfn.IFNA(_xlfn.XLOOKUP(F29,'Fastmoss 500'!D:D,'Fastmoss 500'!O:O),0) -> 0 | K29: =_xlfn.IFNA(_xlfn.XLOOKUP(F29,'Fastmoss 500'!D:D,'Fastmoss 500'!N:N),0) -> 0 | L29: Shp 500 | M29: =IF(L29="Shp 500","Sim",IF(ISNA(_xlfn.XLOOKUP(C29,'Shp 500'!D:D,'Shp 500'!D:D)),"Não","Sim")) -> Sim | N29: =IF(L29="Fastmoss 500","Sim",IF(ISNA(_xlfn.XLOOKUP(_xlfn.XLOOKUP(C29,'Same Seller Hist'!E:E,'Same Seller Hist'!H:H),'Fastmoss 500'!D:D,'Fastmoss 500'!D:D)),"Não","Sim")) -> Não | O29: =IF(AND(M29="Sim",N29="Sim"),"Sim","Não") -> Não | P29: =IF(I29>K29,"Sim","Não") -> Sim | Q29: =COUNTIFS(C:C,C29) -> 2
C30: 378105312 | D30: EssencialBaby | E30: =_xlfn.XLOOKUP(C30,'Same Seller Hist'!E:E,'Same Seller Hist'!I:I) -> 7.496183e+18 | F30: =_xlfn.XLOOKUP(C30,'Same Seller Hist'!E:E,'Same Seller Hist'!H:H) -> Essencial Baby | G30: FMCG | H30: 2847.1935 | I30: 14097.538 | J30: =_xlfn.IFNA(_xlfn.XLOOKUP(F30,'Fastmoss 500'!D:D,'Fastmoss 500'!O:O),0) -> 0 | K30: =_xlfn.IFNA(_xlfn.XLOOKUP(F30,'Fastmoss 500'!D:D,'Fastmoss 500'!N:N),0) -> 0 | L30: Shp 500 | M30: =IF(L30="Shp 500","Sim",IF(ISNA(_xlfn.XLOOKUP(C30,'Shp 500'!D:D,'Shp 500'!D:D)),"Não","Sim")) -> Sim | N30: =IF(L30="Fastmoss 500","Sim",IF(ISNA(_xlfn.XLOOKUP(_xlfn.XLOOKUP(C30,'Same Seller Hist'!E:E,'Same Seller Hist'!H:H),'Fastmoss 500'!D:D,'Fastmoss 500'!D:D)),"Não","Sim")) -> Não | O30: =IF(AND(M30="Sim",N30="Sim"),"Sim","Não") -> Não | P30: =IF(I30>K30,"Sim","Não") -> Sim | Q30: =COUNTIFS(C:C,C30) -> 1
C31: =_xlfn.XLOOKUP(F31,'Same Seller Hist'!H:H,'Same Seller Hist'!E:E) -> 325008325 | D31: =_xlfn.XLOOKUP(F31,'Same Seller Hist'!H:H,'Same Seller Hist'!D:D) -> Na Web | E31: =_xlfn.XLOOKUP(F31,'Same Seller Hist'!H:H,'Same Seller Hist'!I:I) -> 7.4961601e+18 | F31: Na Web | G31: =_xlfn.XLOOKUP(C31,'Same Seller Hist'!E:E,'Same Seller Hist'!F:F) -> Lifestyle | H31: =_xlfn.IFNA(_xlfn.XLOOKUP(C31,'Shp 500'!D:D,'Shp 500'!I:I),0) -> 1795.6129 | I31: =_xlfn.IFNA(_xlfn.XLOOKUP(C31,'Shp 500'!D:D,'Shp 500'!J:J),0) -> 32107.84 | J31: 587.09677 | K31: 54838.71 | L31: Fastmoss 500 | M31: =IF(L31="Shp 500","Sim",IF(ISNA(_xlfn.XLOOKUP(C31,'Shp 500'!D:D,'Shp 500'!D:D)),"Não","Sim")) -> Sim | N31: =IF(L31="Fastmoss 500","Sim",IF(ISNA(_xlfn.XLOOKUP(_xlfn.XLOOKUP(C31,'Same Seller Hist'!E:E,'Same Seller Hist'!H:H),'Fastmoss 500'!D:D,'Fastmoss 500'!D:D)),"Não","Sim")) -> Sim | O31: =IF(AND(M31="Sim",N31="Sim"),"Sim","Não") -> Sim | P31: =IF(I31>K31,"Sim","Não") -> Não | Q31: =COUNTIFS(C:C,C31) -> 2
C32: 328666563 | D32: DAFUSHOP_brasil | E32: =_xlfn.XLOOKUP(C32,'Same Seller Hist'!E:E,'Same Seller Hist'!I:I) -> 7.4961464e+18 | F32: =_xlfn.XLOOKUP(C32,'Same Seller Hist'!E:E,'Same Seller Hist'!H:H) -> DAFUSHOP BRASIL | G32: CN | H32: 2853.6774 | I32: 20794.012 | J32: =_xlfn.IFNA(_xlfn.XLOOKUP(F32,'Fastmoss 500'!D:D,'Fastmoss 500'!O:O),0) -> 2251.6129 | K32: =_xlfn.IFNA(_xlfn.XLOOKUP(F32,'Fastmoss 500'!D:D,'Fastmoss 500'!N:N),0) -> 138709.68 | L32: Shp 500 | M32: =IF(L32="Shp 500","Sim",IF(ISNA(_xlfn.XLOOKUP(C32,'Shp 500'!D:D,'Shp 500'!D:D)),"Não","Sim")) -> Sim | N32: =IF(L32="Fastmoss 500","Sim",IF(ISNA(_xlfn.XLOOKUP(_xlfn.XLOOKUP(C32,'Same Seller Hist'!E:E,'Same Seller Hist'!H:H),'Fastmoss 500'!D:D,'Fastmoss 500'!D:D)),"Não","Sim")) -> Sim | O32: =IF(AND(M32="Sim",N32="Sim"),"Sim","Não") -> Sim | P32: =IF(I32>K32,"Sim","Não") -> Não | Q32: =COUNTIFS(C:C,C32) -> 2
C33: 375201738 | D33: LUCKY BAZAR | E33: =_xlfn.XLOOKUP(C33,'Same Seller Hist'!E:E,'Same Seller Hist'!I:I) -> 7.4961623e+18 | F33: =_xlfn.XLOOKUP(C33,'Same Seller Hist'!E:E,'Same Seller Hist'!H:H) -> Lucky Bazar | G33: CN | H33: 2655.1613 | I33: 11185.769 | J33: =_xlfn.IFNA(_xlfn.XLOOKUP(F33,'Fastmoss 500'!D:D,'Fastmoss 500'!O:O),0) -> 0 | K33: =_xlfn.IFNA(_xlfn.XLOOKUP(F33,'Fastmoss 500'!D:D,'Fastmoss 500'!N:N),0) -> 0 | L33: Shp 500 | M33: =IF(L33="Shp 500","Sim",IF(ISNA(_xlfn.XLOOKUP(C33,'Shp 500'!D:D,'Shp 500'!D:D)),"Não","Sim")) -> Sim | N33: =IF(L33="Fastmoss 500","Sim",IF(ISNA(_xlfn.XLOOKUP(_xlfn.XLOOKUP(C33,'Same Seller Hist'!E:E,'Same Seller Hist'!H:H),'Fastmoss 500'!D:D,'Fastmoss 500'!D:D)),"Não","Sim")) -> Não | O33: =IF(AND(M33="Sim",N33="Sim"),"Sim","Não") -> Não | P33: =IF(I33>K33,"Sim","Não") -> Sim | Q33: =COUNTIFS(C:C,C33) -> 1
